Workbook

Sheet Read me
B2: FBA Season 6 Round 2 consolidated data pack: DNSE Securities
B3: Every dataset behind the DNSE report, in one file. Compiled 20 to 21 September 2026.
B5: What this is | C5: Five datasets in one workbook. DNSE company financials and market position, the Vietnamese securities industry cross-section, 868 cleaned Google Play reviews of DNSE and two competitors, the complete Global Findex record for Vietnam, and a macro reference sheet. Every computed cell is a formula, so editing an input updates everything downstream.
B6: Where the data came from | C6: DNSE financials from its filed statements, every line, pulled from Vietcap's data service on 2026-09-24 and checked against the KPMG-reviewed half-year statements; accounts and plan targets from investor relations releases and the 2026 annual general meeting. Market share from every HOSE and HNX quarterly announcement found for 2018 to Q2 2026, read from the exchanges' own sites by step 01d. Lending and profit for all 42 securities companies with filings, VPS (HOSE: VCK) included, via the same service; only the industry lending total is from the press (Vietstock). Accounts from VSDC annual reports and its homepage counter; index levels and traded value from Vietcap's price service; macro from the World Bank WDI API and NSO releases. Customer figures from the DNSE annual report 2025 and the 2026 plan from the AGM proposals. Findex from the World Bank Open Data API, source 28, country VNM, endpoint api.worldbank.org/v2/sources/28/country/VNM/series/all/data?format=json, which returned 19,878 observations of which 3,022 are non-null. Reviews from the public Google Play listings for vn.com.encapital.arrow, vn.com.vpbs.smartone and com.fpts.eztrade.
B7: How to read the colours | C7: Blue figures are inputs taken directly from a source. Green figures are links to another sheet. Black figures are formulas computed in this workbook. Yellow fill marks an assumption you may want to change. Editing a blue or yellow cell updates every black cell that depends on it.
B8: The review data | C8: 867 DNSE reviews, 1,200 VPS and 177 FPTS, pulled 2026-09-23 and cut at 2026-09-21. The cleaning rule is written out in full on the 'Review analysis' sheet and was applied identically to all three applications, so the comparison is like for like. 197 DNSE reviews were removed as loan advertising, referral farming or duplicates.
B9: Survey waves covered | C9: 2011, 2014, 2017, 2022 and 2024. Note the labelling: the round usually called Global Findex 2021 is filed under 2022 for Vietnam in the World Bank API, and Vietnam's 2021 slot is empty. This workbook uses the API's own year labels. The 2024 wave was published in the Global Findex 2025 release; fieldwork ran May to December 2024.
B10: Sample | C10: 1,000 Vietnamese adults aged 15 and over, 199 variables in the underlying microdata file. All figures here are weighted population estimates, expressed as a percentage of adults aged 15+ unless the label says otherwise.
B11: The microdata | C11: This workbook holds published aggregates. The respondent-level file (1,000 rows, 199 columns) is a separate free download at microdata.worldbank.org/index.php/catalog/7998, reference VNM_2024_FINDEX_v02_M. Download that too if you want to do your own cross-tabulations.
B12: Why the segments matter | C12: Findex publishes every indicator broken down twelve ways: by sex, age band, education, income quintile group, urban or rural, and labour force status. That is a ready-made market segmentation. The 'Segments 2024' sheet is the core table.
B13: A caution on precision | C13: 1,000 respondents split twelve ways leaves small cells. Treat differences of a few percentage points as noise and say so in your report. The large gaps, 30 points and more, are real.
B14: A caution on definitions | C14: Findex says 70.6% of Vietnamese adults aged 15+ had an account in 2024. The State Bank puts payment account penetration above 89% of people aged 15+ for H1 2026. The two are directly comparable in denominator and roughly 18 points apart. Both are defensible: one counts people who report having an account when surveyed, the other counts accounts on bank systems, which includes duplicates one person holds across banks. Findex separately finds only 2.1% of adults holding an inactive account, which does not close the gap. Do not mix them in one chart without saying which is which. Naming the discrepancy is worth marks under evidence transparency.
B15: Verification | C15: Every figure on the 'Vietnam reference' sheet was re-checked against primary or Vietnamese-language sources on 20 September 2026. Twelve claims changed on review, including the small-firm credit access ladder, the biometric verification count, bank asset sizes and the brokerage market share tables. Appendix C of the accompanying report lists each one.
B16: Licence | C16: World Bank Open Data, CC BY 4.0. Cite as: World Bank, Global Findex Database 2025. Reproducing it in a student report is fine; say where it came from.
B18: Sheets in this workbook
B19: DNSE financials | C19: Revenue, cost, profit and balance-sheet lines from the filed statements, with computed margins, revenue mix, funding cost and a quarterly series.
B20: DNSE statements | C20: Every line of DNSE's filed statements, Q1 2024 to Q2 2026, as pulled by step 01b.
B21: Market share | C21: HOSE, HNX and derivatives brokerage share for every firm in the top ten, second quarter of 2026.
B22: Market share history | C22: DNSE, VPS and tenth-place shares on each market by quarter, 2018 to Q2 2026, with DNSE's share of filed lending.
B23: Industry cross-section | C23: Lending balances and pre-tax profit for the largest securities firms, with shares of the industry total.
B24: Broker totals | C24: Lending, equity, revenue, brokerage and profit summed across every filing broker, by quarter from 2018.
B25: DNSE position | C25: The five share measures that define the monetisation gap, each against its own denominator.
B26: Market and macro | C26: Index levels, traded value, VSDC accounts with DNSE's share, World Bank indicators 2018 to 2025, NSO 2026.
B27: Review analysis | C27: Cleaning log, ratings by year, complaint themes and the three-app comparison.
B28: Review quotes | C28: Fifty selected reviews with rating, date, helpfulness votes and theme tags.
B29: Segment model | C29: The derived priority segment. Every index cell is a formula reading from Segments 2024.
B30: Segments 2024 | C30: 51 Findex indicators by all twelve Findex segments, latest wave.
... B35: Sources | C35: Where to get everything else, with links.
B37: Findex segment codes
C38: Indicator ids ending .1 to .12 are segment cuts of the base indicator: .1 women, .2 men, .3 age 15-24, .4 age 25+, .5 primary education or less, .6 secondary or more, .7 poorest 40%, .8 richest 60%, .9 rural, .10 urban, .11 out of the labour force, .12 in the labour force. A suffix of .s means the figure is a share of a sub-population rather than of all adults.

Sheet DNSE financials
A1: DNSE Securities: reported financials
A2: VND billion unless stated. Blue cells are DNSE's filed statements, pulled line by line on 2026-09-24 by 01b_dnse_financials_fetch.py; every line is on the 'DNSE statements' sheet. Black cells are formulas. Q2 2026 is the KPMG-reviewed half year less the first quarter.
A4: Line | B4: FY2025 | C4: Q1 2026 | D4: Q2 2026 | E4: H1 2026 | F4: H1 as % of FY2025 | G4: Note
A5: Operating revenue | B5: 1457.912 | C5: 395.143 | D5: 453.086 | E5: =C5+D5 -> 848.229 | F5: =IF(B5=0,"",E5/B5*100) -> 58.181084
A6: Interest on lending and receivables | B6: 555.797 | C6: 147.475 | D6: 188.602 | E6: =C6+D6 -> 336.077 | F6: =IF(B6=0,"",E6/B6*100) -> 60.467581
A7: Brokerage commissions | B7: 404.02 | C7: 119.524 | D7: 102.535 | E7: =C7+D7 -> 222.059 | F7: =IF(B7=0,"",E7/B7*100) -> 54.962378 | G7: Majority derivatives
A8: Interest on held-to-maturity investments | B8: 303.91 | C8: 98.396 | D8: 95.043 | E8: =C8+D8 -> 193.439 | F8: =IF(B8=0,"",E8/B8*100) -> 63.650094
A9: Gains on FVTPL financial assets | B9: 171.39 | C9: 23.464 | D9: 53.76 | E9: =C9+D9 -> 77.224 | F9: =IF(B9=0,"",E9/B9*100) -> 45.057471 | G9: Proprietary trading gains, before the losses below
A10: Other revenue | B10: =B5-SUM(B6:B9) -> 22.795 | C10: =C5-SUM(C6:C9) -> 6.284 | D10: =D5-SUM(D6:D9) -> 13.146 | E10: =C10+D10 -> 19.43 | F10: =IF(B10=0,"",E10/B10*100) -> 85.237991 | G10: Operating revenue less the four lines above: custody, advisory, underwriting and other
A11: Financial income | B11: 7.532 | C11: 2.273 | D11: 2.004 | E11: =C11+D11 -> 4.277 | F11: =IF(B11=0,"",E11/B11*100) -> 56.784387 | G11: Outside operating revenue: interest on demand deposits
A12: Revenue including financial income | B12: =B5+B11 -> 1465.444 | C12: =C5+C11 -> 397.416 | D12: =D5+D11 -> 455.09 | E12: =C12+D12 -> 852.506 | F12: =IF(B12=0,"",E12/B12*100) -> 58.173905 | G12: The basis of the 2026 plan (Proposal 05/2026: 'total revenue'). With other income of about 1.6 it gives the annual report's VND 1,467 billion for 2025
A13: Brokerage direct costs | B13: -464.856 | C13: -137.816 | D13: -128.702 | E13: =C13+D13 -> -266.518 | F13: =IF(B13=0,"",E13/B13*100) -> 57.333454 | G13: Costs are negative, as filed
A14: Losses on FVTPL financial assets | B14: -25.209 | C14: -33.075 | D14: -10.284 | E14: =C14+D14 -> -43.359 | F14: =IF(B14=0,"",E14/B14*100) -> 171.9981
A15: Provisions and loan funding cost | B15: -362.988 | C15: -122.82 | D15: -126.106 | E15: =C15+D15 -> -248.926 | F15: =IF(B15=0,"",E15/B15*100) -> 68.576923 | G15: Template line 24 reports loan-loss provisions and the borrowing cost of the loan book as one figure. The loan-loss allowance below moves by a few billion a quarter, so most of this is funding cost
A16: Interest expense | B16: -66.827 | C16: -37.747 | D16: -37.464 | E16: =C16+D16 -> -75.211 | F16: =IF(B16=0,"",E16/B16*100) -> 112.54583
A17: Company administration costs | B17: -181.404 | C17: -46.086 | D17: -49.346 | E17: =C17+D17 -> -95.432 | F17: =IF(B17=0,"",E17/B17*100) -> 52.60744
A18: Pre-tax profit | B18: 340.225 | C18: 14.171 | D18: 97.436 | E18: =C18+D18 -> 111.607 | F18: =IF(B18=0,"",E18/B18*100) -> 32.80388 | G18: The quarterly statement of 20 July 2026 gave Q2 98.9 and H1 113.1. The half year reviewed by KPMG on 14 August gives H1 111.6, and Q2 here is that less Q1
A19: Profit after tax | B19: 272.53 | C19: 11.327 | D19: 81.801 | E19: =C19+D19 -> 93.128 | F19: =IF(B19=0,"",E19/B19*100) -> 34.171651
A20: Margin loans and advances, period end | B20: 5832.191 | C20: 5909.548 | D20: 6303.065 | E20: =D20 -> 6303.065 | G20: Balance, not a flow. H1 equals the Q2 closing balance. Q2 2026 is a record for the firm
A21: Loan-loss allowance, period end | B21: -54.119 | C21: -57.35 | D21: -63.083 | E21: =D21 -> -63.083 | G21: Negative, as filed
A22: Shareholders' equity, period end | B22: 4302.33 | C22: 5358.446 | D22: 5440.246 | E22: =D22 -> 5440.246
A23: Borrowings and bonds issued, period end | B23: 10600.025 | C23: 9976.4 | D23: 9446.164 | E23: =D23 -> 9446.164 | G23: Short-term borrowing plus bonds, short and long
A24: Customer cash held for trading, period end | B24: 2902.961 | C24: 2868.869 | D24: 1960.82 | E24: =D24 -> 1960.82 | G24: Off balance sheet
A25: Customer securities at VSDC, par value, period end | B25: 18471.406 | C25: 21885.34 | D25: 23231.235 | E25: =D25 -> 23231.235 | G25: Off balance sheet, at par value as the template requires, so it understates market value
A27: Computed ratios
A28: Ratio | B28: FY2025 | C28: Q1 2026 | D28: Q2 2026 | E28: H1 2026 | G28: Note
A29: Pre-tax profit margin, per cent | B29: =B18/B5*100 -> 23.336457 | C29: =C18/C5*100 -> 3.5862966 | D29: =D18/D5*100 -> 21.504968 | E29: =E18/E5*100 -> 13.15765 | G29: Falls from 23.3 in 2025 to 13.2 at the 2026 half year
A30: Interest on lending and receivables, share of revenue | B30: =B6/B5*100 -> 38.122809 | C30: =C6/C5*100 -> 37.321932 | D30: =D6/D5*100 -> 41.626093 | E30: =E6/E5*100 -> 39.621022
A31: Brokerage commissions, share of revenue | B31: =B7/B5*100 -> 27.712235 | C31: =C7/C5*100 -> 30.24829 | D31: =D7/D5*100 -> 22.630362 | E31: =E7/E5*100 -> 26.179133
A32: Interest on held-to-maturity investments, share of revenue | B32: =B8/B5*100 -> 20.845565 | C32: =C8/C5*100 -> 24.901365 | D32: =D8/D5*100 -> 20.976812 | E32: =E8/E5*100 -> 22.805044
A33: Gains on FVTPL financial assets, share of revenue | B33: =B9/B5*100 -> 11.755854 | C33: =C9/C5*100 -> 5.9381034 | D33: =D9/D5*100 -> 11.865297 | E33: =E9/E5*100 -> 9.1041452
A34: Lending, held-to-maturity and FVTPL income, share of revenue | B34: =(B6+B8+B9)/B5*100 -> 70.724228 | C34: =(C6+C8+C9)/C5*100 -> 68.1614 | D34: =(D6+D8+D9)/D5*100 -> 74.468203 | E34: =(E6+E8+E9)/E5*100 -> 71.530212 | G34: Revenue that depends on balance sheet size and market direction rather than on customer trading
A35: Brokerage result after direct costs, VND bn | B35: =B7+B13 -> -60.836 | C35: =C7+C13 -> -18.292 | D35: =D7+D13 -> -26.167 | E35: =E7+E13 -> -44.459 | G35: Negative in every quarter since 2022 Q3
A36: Lending to equity, per cent | B36: =B20/B22*100 -> 135.55889 | C36: =C20/C22*100 -> 110.28474 | D36: =D20/D22*100 -> 115.85993 | E36: =E20/E22*100 -> 115.85993 | G36: The regulatory ceiling on margin lending is 200 per cent of equity
A38: Customers, plan and yield
A39: Item | B39: Value | C39: Unit | G39: Source or formula
A40: Customer accounts, end 2025 | B40: 1512920 | C40: accounts | G40: DNSE annual report 2025, p. 29: 1,512,920 accounts at 31 December 2025
A41: Customer accounts, Q1 2026 | B41: 1650000 | C41: accounts | G41: DNSE statement with Q1 2026 results, as reported by the press
A42: Customer accounts, H1 2026 | B42: 1700000 | C42: accounts | G42: DNSE statement with H1 2026 results, 'over 1.7 million', as reported by the press
A43: New accounts opened, 2025 | B43: 518514 | C43: accounts | G43: DNSE annual report 2025, p. 29
...

Sheet DNSE statements
A1: DNSE Securities: every line of the filed statements
A2: VND billion unless the unit column says otherwise. Pulled from Vietcap's data service on 2026-09-24 by 01b_dnse_financials_fetch.py; field codes are Vietcap's. The full history from Q1 2018 is in dnse_financials_quarterly.csv.
A4: Statement | B4: Field | C4: Line (Vietnamese) | D4: Line (English) | E4: Unit | F4: Q1 2024 | G4: Q2 2024 | H4: Q3 2024 | I4: Q4 2024 | J4: Q1 2025 | K4: Q2 2025 | L4: Q3 2025 | M4: Q4 2025 | N4: Q1 2026 | O4: Q2 2026
A5: income statement | B5: isa1 | C5: DOANH THU HOẠT ĐỘNG | D5: OPERATING SALES | E5: VND bn | F5: 181.5016 | G5: 198.2423 | H5: 193.7291 | I5: 233.9389 | J5: 243.3988 | K5: 290.2315 | L5: 489.458 | M5: 434.824 | N5: 395.1427 | O5: 453.0858
A6: income statement | B6: iss115 | C6: Lãi từ các tài sản tài chính ghi nhận thông qua lãi/lỗ ( FVTPL) | D6: Income from financial assets recognized through profit/loss (FVTPL) | E6: VND bn | F6: 15.9541 | G6: 9.7495 | H6: 9.9453 | I6: 12.2188 | J6: 17.5442 | K6: 29.7727 | L6: 71.1156 | M6: 52.9573 | N6: 23.4637 | O6: 53.7595
A7: income statement | B7: iss116 | C7: Lãi bán các tài sản tài chính FVTPL | D7: Income from selling financial assets FVTPL | E7: VND bn | F7: 14.4754 | G7: 18.3868 | H7: 8.2146 | I7: 7.5232 | J7: 2.8541 | K7: 18.7998 | L7: 57.2299 | M7: 56.0517 | N7: 14.2186 | O7: 13.4577
A8: income statement | B8: iss117 | C8: Chênh lệch tăng đánh giá lại các TSTC thông qua lãi/lỗ | D8: FVTPL revaluation gain | E8: VND bn | F8: 3.4189 | G8: -3.4508 | H8: 0.0842 | I8: -0.0604 | J8: 8.2259 | K8: 10.7868 | L8: 10.2348 | M8: -28.8946 | N8: -0.001 | O8: 1.6654
A9: income statement | B9: iss118 | C9: Cổ tức, tiền lãi phát sinh từ tài sản tài chính FVTPL | D9: Dividend, interest from FVTPL financial assets | E9: VND bn | F9: -1.9403 | G9: -5.1865 | H9: 1.6465 | I9: 4.756 | J9: 6.4642 | K9: 0.1861 | L9: 3.651 | M9: 25.8002 | N9: 9.246 | O9: 38.6363
A10: income statement | B10: iss119 | C10: Lãi từ các khoản đầu tư nắm giữ đến ngày đáo hạn | D10: Income from held to maturity investment (HTM) | E10: VND bn | F10: 57.0633 | G10: 58.7927 | H10: 55.0898 | I10: 74.0859 | J10: 70.4172 | K10: 57.6732 | L10: 85.6077 | M10: 90.2119 | N10: 98.3959 | O10: 95.0426
A11: income statement | B11: iss120 | C11: Lãi từ các khoản cho vay và phải thu | D11: Income from loans and receivables | E11: VND bn | F11: 74.2024 | G11: 87.578 | H11: 93.4178 | I11: 105.3503 | J11: 103.7103 | K11: 125.0635 | L11: 171.1713 | M11: 155.8514 | N11: 147.4746 | O11: 188.6022
A12: income statement | B12: iss42 | C12: Doanh thu nghiệp vụ môi giới chứng khoán | D12: Revenue in Brokerage services | E12: VND bn | F12: 32.1118 | G12: 40.2249 | H12: 33.0443 | I12: 39.4576 | J12: 48.9966 | K12: 73.8502 | L12: 156.1686 | M12: 125.0046 | N12: 119.5236 | O12: 102.5346
A13: income statement | B13: iss44 | C13: Doanh thu nghiệp vụ bảo lãnh phát hành chứng khoán | D13: Revenue in Underwriting services | E13: VND bn | F13: 0 | G13: 0 | H13: 0 | I13: 0 | J13: 0 | K13: 0 | L13: 0 | M13: 2.918 | N13: 0.738 | O13: 0
A14: income statement | B14: iss46 | C14: Doanh thu nghiệp vụ tư vấn đầu tư chứng khoán | D14: Revenue in Stock Investment Advisory services | E14: VND bn | F14: 0 | G14: 0 | H14: 0 | I14: 0.6828 | J14: 0 | K14: 0.1871 | L14: 0.2948 | M14: 0.4443 | N14: 0.3187 | O14: 0.3137
A15: income statement | B15: iss47 | C15: Doanh thu lưu ký chứng khoán | D15: Revenue in Securities custody services | E15: VND bn | F15: 1.3164 | G15: 1.4919 | H15: 1.4465 | I15: 1.3924 | J15: 1.6092 | K15: 1.8582 | L15: 2.2462 | M15: 2.2184 | N15: 2.1959 | O15: 2.3158
A16: income statement | B16: iss123 | C16: Doanh thu hoạt động tư vấn tài chính | D16: Revenue in Financial Advisory services | E16: VND bn | F16: 0 | G16: 0 | H16: 0 | I16: 0 | J16: 0 | K16: 0 | L16: 0 | M16: 2.0446 | N16: 0.1309 | O16: 6.8154
... A365: note | B365: nos353 | C365: Chi phí khác bằng tiền | D365: Other cash expenses | E365: VND bn | F365: 4.3854 | G365: 4.3289 | H365: 3.7967 | I365: 4.0991 | J365: 4.2415 | K365: 2.8398 | L365: 4.2383 | M365: 4.7955 | N365: 5.7051 | O365: 4.7435

Sheet Market share
A1: Brokerage market share, second quarter of 2026
A2: Each percentage is a share of traded value on the named market. Shares from different markets are not comparable with one another. Sources: the HOSE and HNX quarterly announcements themselves, read by 01d_market_macro_fetch.py. A blank cell means the firm was outside that market's published top ten.
A4: Firm | B4: HOSE Q2 2026 | C4: HOSE Q1 2026 | D4: HOSE change, points | E4: HNX Q2 2026 | F4: Derivatives Q2 2026 | G4: Note
A5: VPS | B5: 12.61 | C5: 15.32 | D5: =IF(OR(B5="",C5=""),"",B5-C5) -> -2.71 | E5: 17.71 | F5: 33.84 | G5: Leads every market but lost 2.71 points of HOSE share in one quarter
A6: SSI | B6: 11.17 | C6: 11.14 | D6: =IF(OR(B6="",C6=""),"",B6-C6) -> 0.03 | E6: 6.58 | F6: 8.21
A7: TCBS | B7: 9.36 | C7: 8.85 | D7: =IF(OR(B7="",C7=""),"",B7-C7) -> 0.51 | E7: 9 | F7: 4.83 | G7: Largest lending book among filing brokers
A8: Vietcap | B8: 7 | C8: 7.35 | D8: =IF(OR(B8="",C8=""),"",B8-C8) -> -0.35 | E8: 2.86
A9: HSC | B9: 6.8 | C9: 7.3 | D9: =IF(OR(B9="",C9=""),"",B9-C9) -> -0.5 | F9: 9.23
A10: MBS | B10: 4.79 | C10: 5.29 | D10: =IF(OR(B10="",C10=""),"",B10-C10) -> -0.5 | E10: 5.34 | F10: 4
A11: VNDirect | B11: 3.96 | C11: 4.78 | D11: =IF(OR(B11="",C11=""),"",B11-C11) -> -0.82 | E11: 5.88 | F11: 4.01
A12: VPBankS | B12: 3.57 | C12: 2.94 | D12: =IF(OR(B12="",C12=""),"",B12-C12) -> 0.63 | E12: 6.71 | G12: Largest gainer of the quarter on both exchanges
A13: KIS Vietnam | B13: 2.99 | C13: 3.21 | D13: =IF(OR(B13="",C13=""),"",B13-C13) -> -0.22
A14: Mirae Asset Vietnam | B14: 2.94 | D14: =IF(OR(B14="",C14=""),"",B14-C14) | F14: 1.82
A15: VCBS | C15: 2.87 | D15: =IF(OR(B15="",C15=""),"",B15-C15) | G15: In the HOSE top ten in Q1 only
A16: BSC | D16: =IF(OR(B16="",C16=""),"",B16-C16) | E16: 3.58
A17: DNSE | D17: =IF(OR(B17="",C17=""),"",B17-C17) | E17: 2.88 | F17: 25.38 | G17: Second in derivatives, eighth on HNX, outside the top ten on HOSE
A18: VIX | D18: =IF(OR(B18="",C18=""),"",B18-C18) | E18: 2.66
A19: FPTS | D19: =IF(OR(B19="",C19=""),"",B19-C19) | F19: 1.91
A20: PHS | D20: =IF(OR(B20="",C20=""),"",B20-C20) | F20: 1.29
A21: Sum of the firms listed above | B21: =SUM(B5:B20) -> 65.19 | C21: =SUM(C5:C20) -> 69.05 | E21: =SUM(E5:E20) -> 63.2 | F21: =SUM(F5:F20) -> 94.52 | G21: Each column is a full top ten, so each sum equals the top-ten total below
A22: Top ten combined | B22: 65.19 | C22: 69.05 | E22: 63.2 | F22: 94.52 | G22: Share left to every firm outside the top ten = 100 less this row
A25: DNSE derivatives brokerage share by quarter
A26: Quarter | B26: Share, per cent | C26: Change on previous, points | G26: Source
A27: Q1 2024 | B27: 4.01 | G27: HNX quarterly announcement
A28: Q2 2024 | B28: 5.11 | C28: =B28-B27 -> 1.1 | G28: HNX quarterly announcement
A29: Q3 2024 | B29: 5.3 | C29: =B29-B28 -> 0.19 | G29: HNX quarterly announcement
A30: Q4 2024 | B30: 9.98 | C30: =B30-B29 -> 4.68 | G30: HNX quarterly announcement
A31: Q1 2025 | B31: 16.72 | C31: =B31-B30 -> 6.74 | G31: HNX quarterly announcement
A32: Q2 2025 | B32: 17.62 | C32: =B32-B31 -> 0.9 | G32: HNX quarterly announcement
A33: Q3 2025 | B33: 23.67 | C33: =B33-B32 -> 6.05 | G33: HNX quarterly announcement
A34: Q4 2025 | B34: 24.26 | C34: =B34-B33 -> 0.59 | G34: HNX quarterly announcement
A35: Q1 2026 | B35: 25.5 | C35: =B35-B34 -> 1.24 | G35: HNX quarterly announcement
A36: Q2 2026 | B36: 25.38 | C36: =B36-B35 -> -0.12 | G36: HNX quarterly announcement
A37: DNSE entered the derivatives top ten in Q1 2024; the full quarterly history from 2018 is on the Market share history tab.

Sheet Market share history
A1: Brokerage market share by quarter, 2018 to Q2 2026
A2: Read from every HOSE and HNX quarterly announcement that 01d could find. A blank DNSE cell means DNSE was outside that market's top ten, so its share was below the tenth-place figure beside it. A row with no figures at all means no announcement was found for that quarter. HOSE's news service holds 2023 onwards plus two older quarters.
A4: Quarter | B4: HOSE top ten combined | C4: HOSE tenth place | D4: HOSE VPS | E4: HNX listed DNSE | F4: HNX listed tenth place | G4: UPCoM DNSE | H4: UPCoM tenth place | I4: Derivatives DNSE | J4: Derivatives DNSE rank | K4: Derivatives tenth place | L4: Derivatives VPS | M4: Derivatives top ten combined | N4: DNSE share of filed lending | O4: Brokers filing
A5: Q1 2018 | F5: 3.42 | H5: 4.21 | L5: 8.39 | M5: 99.99 | N5: 0.075 | O5: 40
A6: Q2 2018 | F6: 3.56 | N6: 0.079 | O6: 42
A7: Q3 2018 | F7: 3.39 | H7: 3.48 | N7: 0.06 | O7: 42
A8: Q4 2018 | B8: 68.86 | C8: 2.8 | D8: 2.87 | F8: 4.02 | H8: 4.03 | K8: 0.69 | L8: 21.79 | M8: 99.34 | N8: 0.054 | O8: 43
A9: Q1 2019 | B9: 65.23 | C9: 3.11 | D9: 3.14 | F9: 3.61 | H9: 4.19 | K9: 1.21 | L9: 37.5 | M9: 97.8 | N9: 0.09 | O9: 42
A10: Q2 2019 | F10: 3.44 | H10: 3.43 | K10: 0.93 | L10: 51.82 | M10: 97.95 | N10: 0.111 | O10: 41
A11: Q3 2019 | F11: 3.75 | H11: 3.32 | K11: 0.93 | L11: 55.92 | M11: 98.33 | N11: 0.091 | O11: 42
A12: Q4 2019 | F12: 3.57 | H12: 3.45 | K12: 0.89 | L12: 59.57 | M12: 97.02 | N12: 0.08 | O12: 42
A13: Q1 2020 | F13: 3.36 | H13: 3.02 | K13: 1.14 | L13: 55.4 | M13: 94.93 | N13: 0.102 | O13: 42
A14: Q2 2020 | F14: 3.79 | H14: 4.11 | K14: 1.35 | L14: 51.18 | M14: 95.4 | N14: 0.15 | O14: 42
A15: Q3 2020 | F15: 4.15 | H15: 4.14 | K15: 1.22 | L15: 52.05 | M15: 94.24 | N15: 0.031 | O15: 42
A16: Q4 2020 | F16: 3.7 | H16: 3.91 | K16: 1.14 | L16: 56.1 | M16: 95.84 | N16: 0.037 | O16: 42
A17: Q1 2021 | F17: 3.75 | H17: 3.82 | K17: 0.95 | L17: 53.99 | M17: 95.28 | N17: 0.089 | O17: 42
A18: Q2 2021 | F18: 3.46 | H18: 3.55 | K18: 0.95 | L18: 54.58 | M18: 96.96 | N18: 0.168 | O18: 39
A19: Q3 2021 | F19: 2.82 | H19: 3.1 | K19: 0.99 | L19: 56.68 | M19: 96.72 | N19: 0.52 | O19: 38
A20: Q4 2021 | F20: 2.82 | H20: 2.91 | K20: 1.18 | L20: 56.21 | M20: 95.53 | N20: 0.86 | O20: 39
A21: Q1 2022 | F21: 2.74 | H21: 2.81 | K21: 1.32 | L21: 53.84 | M21: 94.56 | N21: 0.936 | O21: 40
A22: Q2 2022 | E22: 3.79 | F22: 2.98 | H22: 2.78 | K22: 1.42 | L22: 56.06 | M22: 94.62 | N22: 1.785 | O22: 40
A23: Q3 2022 | F23: 2.69 | H23: 2.77 | K23: 1.42 | L23: 60.98 | M23: 94.64 | N23: 2.139 | O23: 39
A24: Q4 2022 | F24: 3.1 | H24: 3.24 | K24: 1.79 | L24: 58.58 | M24: 93.82 | N24: 2.742 | O24: 38
A25: Q1 2023 | B25: 66.76 | C25: 3.03 | D25: 15.67 | F25: 2.87 | H25: 3.05 | K25: 1.43 | L25: 61.54 | M25: 94.52 | N25: 2.859 | O25: 40
A26: Q2 2023 | B26: 68.08 | C26: 3.23 | D26: 19.01 | F26: 2.71 | H26: 3.33 | K26: 1.59 | L26: 60.64 | M26: 93.36 | N26: 2.519 | O26: 40
A27: Q3 2023 | B27: 69.76 | C27: 3.04 | D27: 19.92 | F27: 2.44 | H27: 3 | K27: 1.47 | L27: 56.16 | M27: 93.1 | N27: 1.932 | O27: 40
A28: Q4 2023 | B28: 69.84 | C28: 2.84 | D28: 19.92 | F28: 2.35 | H28: 2.38 | K28: 1.57 | L28: 58.01 | M28: 93.62 | N28: 1.913 | O28: 40
A29: Q1 2024 | B29: 69.13 | C29: 2.82 | D29: 20.29 | I29: 4.01 | J29: 5 | K29: 1.96 | L29: 58.9 | M29: 93.55 | N29: 2.306 | O29: 39
A30: Q2 2024 | B30: 68.11 | C30: 2.87 | D30: 18.16 | F30: 2.6 | H30: 2.82 | I30: 5.11 | J30: 4 | K30: 1.97 | L30: 58.77 | M30: 93.91 | N30: 2.232 | O30: 41
A31: Q3 2024 | B31: 67.81 | C31: 2.96 | D31: 17.63 | F31: 3.06 | H31: 2.7 | I31: 5.3 | J31: 3 | K31: 2.04 | L31: 58.92 | M31: 93.68 | N31: 2.48 | O31: 41
A32: Q4 2024 | B32: 68.04 | C32: 2.84 | D32: 16.45 | F32: 3.06 | H32: 3.55 | I32: 9.98 | J32: 2 | K32: 2.06 | L32: 55.84 | M32: 94.51 | N32: 2.206 | O32: 40
A33: Q1 2025 | B33: 68.37 | C33: 2.92 | D33: 16.94 | F33: 2.85 | H33: 3.39 | I33: 16.72 | J33: 2 | K33: 2 | L33: 50.64 | M33: 95.58 | N33: 2.131 | O33: 40
A34: Q2 2025 | B34: 68.49 | C34: 2.91 | D34: 15.37 | F34: 3.08 | H34: 3.13 | I34: 17.62 | J34: 2 | K34: 2.06 | L34: 46.39 | M34: 91.76 | N34: 2.297 | O34: 40
A35: Q3 2025 | B35: 69.05 | C35: 2.87 | D35: 17.05 | E35: 4.63 | F35: 2.65 | H35: 2.9 | I35: 23.67 | J35: 2 | K35: 2.09 | L35: 36.14 | M35: 93.02 | N35: 2.05 | O35: 40
A36: Q4 2025 | B36: 68.13 | C36: 2.82 | D36: 14.28 | F36: 2.63 | H36: 2.86 | I36: 24.26 | J36: 2 | K36: 1.73 | L36: 33.83 | M36: 93.77 | N36: 1.847 | O36: 42
A37: Q1 2026 | B37: 69.05 | C37: 2.87 | D37: 15.32 | F37: 2.69 | G37: 2.49 | H37: 2.49 | I37: 25.5 | J37: 2 | K37: 1.51 | L37: 33.34 | M37: 93.53 | N37: 1.837 | O37: 41
A38: Q2 2026 | B38: 65.19 | C38: 2.94 | D38: 12.61 | E38: 2.88 | F38: 2.66 | H38: 2.91 | I38: 25.38 | J38: 2 | K38: 1.29 | L38: 33.84 | M38: 94.52 | N38: 1.825 | O38: 42
A40: HNX announcements used | B40: 139 | C40: Links to each are in market_macro.json under hnx_market_share.notices_used
A41: Filed lending | C41: DNSE's loan book over the sum of loan books of every securities company with filings on Vietcap's service (step 01c). The number of firms filing changes over time, which is shown in the last column.

Sheet Industry cross-section
A1: Vietnamese securities industry, second quarter of 2026
A2: Lending balances and pre-tax profit from quarterly financial statements. Shares are formulas against the industry total in the assumption cell below.
A4: Firm | B4: Lending balance, VND bn | C4: Share of industry, per cent | D4: Q2 2026 pre-tax profit, VND bn | E4: HOSE brokerage share, per cent | F4: Note
A5: TCBS | B5: 51522.4 | C5: =IF(B5="","",B5/$B$17*100) -> 11.353548 | D5: 2097 | E5: 9.36 | F5: Year on year +21.0%
A6: SSI | B6: 40472.6 | C6: =IF(B6="","",B6/$B$17*100) -> 8.9185985 | D6: 1529 | E6: 11.17 | F6: Year on year +27.6%
A7: VPBankS | B7: 38177.2 | C7: =IF(B7="","",B7/$B$17*100) -> 8.412781 | D7: 2158.6 | E7: 3.57 | F7: Year on year +293.2%
A8: VPS | B8: 31311.5 | C8: =IF(B8="","",B8/$B$17*100) -> 6.8998457 | D8: 1378.4 | E8: 12.61 | F8: Year on year +56.8%
A9: HSC | B9: 29023.5 | C9: =IF(B9="","",B9/$B$17*100) -> 6.3956589 | D9: 340.5 | E9: 6.8 | F9: Year on year +42.0%
A10: Vietcap | B10: 17145.8 | C10: =IF(B10="","",B10/$B$17*100) -> 3.7782724 | D10: 270.8 | E10: 7 | F10: Year on year +28.1%
A11: MBS | B11: 16828.1 | C11: =IF(B11="","",B11/$B$17*100) -> 3.7082636 | D11: 377.2 | E11: 4.79 | F11: Year on year +38.4%
A12: VIX | B12: 13958.1 | C12: =IF(B12="","",B12/$B$17*100) -> 3.0758264 | D12: 75.3 | F12: Year on year -95.3%
A13: VNDirect | B13: 12859 | C13: =IF(B13="","",B13/$B$17*100) -> 2.8336271 | D13: 1105.5 | E13: 3.96 | F13: Year on year +126.5%
A14: SHS | B14: 11722.1 | C14: =IF(B14="","",B14/$B$17*100) -> 2.5830983 | D14: 89.7 | F14: Year on year -80.6%
A15: DNSE | B15: 6303.1 | C15: =IF(B15="","",B15/$B$17*100) -> 1.3889599 | D15: 97.4 | F15: Year on year +7.0%
A16: Firms listed above | B16: =SUM(B5:B15) -> 269323.4 | C16: =B16/$B$17*100 -> 59.34848 | D16: =SUM(D5:D15) -> 9519.4
A17: Industry total lending | B17: 453800 | F17: The 453,800 figure is total lending, which includes advances against sale proceeds. Press estimates of margin lending alone for the same date cluster around 445,000. The firms with filings on Vietcap, listed and UPCoM brokers, account for about three quarters of it.
A19: Previous quarter industry total | B19: 424100 | C19: =(B17-B19)/B19*100 -> 7.0030653 | F19: Quarterly growth in industry lending, per cent, reported as 7
A20: All 42 brokers with filings, lending 30 June 2026 | B20: 345308.5 | C20: =B20/B17*100 -> 76.092662 | F20: Sum of every securities company's filed loan book (step 01c); share of the press industry total
A21: Same brokers, 31 March 2026 | B21: 321726.7 | C21: =(B20-B21)/B21*100 -> 7.3297616 | F21: Quarterly growth of the filed total, per cent: a check on the reported 7

Sheet Broker totals
A1: Every securities company with filings, summed by quarter
A2: VND billion. Each line is the sum across every firm that reported it that quarter, DNSE included, from the statements pulled by 01c. Unlisted foreign-owned brokers do not file here, so the lending total sits about a quarter below the industry figure the press compiles.
A4: Quarter | B4: Firms filing | C4: Lending | D4: Equity | E4: Lending to equity, per cent | F4: Operating revenue | G4: Brokerage revenue | H4: Brokerage direct cost | I4: Pre-tax profit | J4: Customer cash for trading | K4: DNSE lending | L4: DNSE share of lending, per cent
A5: Q1 2018 | B5: 40 | C5: 39222.987 | D5: 44590.105 | E5: =IF(D5=0,"",C5/D5*100) -> 87.963433 | F5: 5616.106 | G5: 1748.392 | H5: -866.814 | I5: 2593.577 | J5: 17876.996 | K5: 29.3652 | L5: =IF(C5=0,"",K5/C5*100) -> 0.074867322
A6: Q2 2018 | B6: 42 | C6: 33835.607 | D6: 45211.504 | E6: =IF(D6=0,"",C6/D6*100) -> 74.83849 | F6: 5195.73 | G6: 1647.226 | H6: -926.944 | I6: 1544.945 | J6: 16099.415 | K6: 26.5744 | L6: =IF(C6=0,"",K6/C6*100) -> 0.078539747
A7: Q3 2018 | B7: 42 | C7: 37195.603 | D7: 48624.103 | E7: =IF(D7=0,"",C7/D7*100) -> 76.496225 | F7: 4761.519 | G7: 1127.533 | H7: -717.17 | I7: 2394.747 | J7: 16440.543 | K7: 22.3861 | L7: =IF(C7=0,"",K7/C7*100) -> 0.060184802
A8: Q4 2018 | B8: 43 | C8: 34649.083 | D8: 51196.332 | E8: =IF(D8=0,"",C8/D8*100) -> 67.678839 | F8: 5806.259 | G8: 1134.069 | H8: -775.56 | I8: 2134.415 | J8: 12847.204 | K8: 18.7363 | L8: =IF(C8=0,"",K8/C8*100) -> 0.054074447
A9: Q1 2019 | B9: 42 | C9: 35641.112 | D9: 52969.332 | E9: =IF(D9=0,"",C9/D9*100) -> 67.286316 | F9: 4291.41 | G9: 842.182 | H9: -661.144 | I9: 1624.944 | J9: 18266.65 | K9: 31.9864 | L9: =IF(C9=0,"",K9/C9*100) -> 0.089745797
A10: Q2 2019 | B10: 41 | C10: 38879.756 | D10: 55139.456 | E10: =IF(D10=0,"",C10/D10*100) -> 70.511679 | F10: 4959.531 | G10: 927.407 | H10: -664.599 | I10: 1565.16 | J10: 14202.09 | K10: 42.9762 | L10: =IF(C10=0,"",K10/C10*100) -> 0.11053619
A11: Q3 2019 | B11: 42 | C11: 38947.608 | D11: 57186.414 | E11: =IF(D11=0,"",C11/D11*100) -> 68.1064 | F11: 5034.063 | G11: 953.499 | H11: -686.526 | I11: 1677.925 | J11: 13631.369 | K11: 35.5904 | L11: =IF(C11=0,"",K11/C11*100) -> 0.091380195
A12: Q4 2019 | B12: 42 | C12: 38595.409 | D12: 58949.224 | E12: =IF(D12=0,"",C12/D12*100) -> 65.472294 | F12: 6647.084 | G12: 1002.59 | H12: -783.894 | I12: 2465.66 | J12: 11903.68 | K12: 31.0106 | L12: =IF(C12=0,"",K12/C12*100) -> 0.080347898
A13: Q1 2020 | B13: 42 | C13: 32820.032 | D13: 59068.687 | E13: =IF(D13=0,"",C13/D13*100) -> 55.562488 | F13: 5625.192 | G13: 833.243 | H13: -638.722 | I13: 490.279 | J13: 17111.546 | K13: 33.6096 | L13: =IF(C13=0,"",K13/C13*100) -> 0.10240575
A14: Q2 2020 | B14: 42 | C14: 35435.31 | D14: 61005.066 | E14: =IF(D14=0,"",C14/D14*100) -> 58.085848 | F14: 7119.901 | G14: 1167.932 | H14: -878.242 | I14: 3602.648 | J14: 21057.724 | K14: 53.1205 | L14: =IF(C14=0,"",K14/C14*100) -> 0.14990838
A15: Q3 2020 | B15: 42 | C15: 42379.853 | D15: 63143.669 | E15: =IF(D15=0,"",C15/D15*100) -> 67.116551 | F15: 6623.368 | G15: 1258.095 | H15: -862.01 | I15: 3056.865 | J15: 22962.968 | K15: 13.2093 | L15: =IF(C15=0,"",K15/C15*100) -> 0.03116882
A16: Q4 2020 | B16: 42 | C16: 62355.188 | D16: 66697.506 | E16: =IF(D16=0,"",C16/D16*100) -> 93.489535 | F16: 9293.301 | G16: 1940.142 | H16: -1264.702 | I16: 3911.396 | J16: 34589.284 | K16: 23.0967 | L16: =IF(C16=0,"",K16/C16*100) -> 0.037040543
... A38: Q2 2026 | B38: 42 | C38: 345308.55 | D38: 358333.73 | E38: =IF(D38=0,"",C38/D38*100) -> 96.365069 | F38: 28242.656 | G38: 2945.418 | H38: -2537.937 | I38: 11870.741 | J38: 56376.847 | K38: 6303.0648 | L38: =IF(C38=0,"",K38/C38*100) -> 1.8253428

Sheet DNSE position
A1: Where DNSE is large and where it is small
A2: Each row compares DNSE against its own denominator. The five denominators differ, so the rows measure position in five separate markets rather than five slices of one market.
A4: Measure | B4: DNSE | C4: Market total | D4: Unit | E4: DNSE share, per cent | F4: Source
A5: Customer accounts | B5: 1700000 | C5: 13887603 | D5: accounts | E5: =IF(B5="","",B5/C5*100) -> 12.241133 | F5: DNSE: 1.7 million at 30 June 2026, company statement. Market: VSDC homepage counter of investor trading accounts, 2026-09-24. The dates differ, which understates DNSE's share slightly
A6: Derivatives brokerage | B6: 25.38 | C6: 100 | D6: per cent of traded value | E6: =IF(B6="","",B6/C6*100) -> 25.38 | F6: HNX Q2 2026 announcement, rank 2 of 10
A7: HNX listed-share brokerage | B7: 2.88 | C7: 100 | D7: per cent of traded value | E7: =IF(B7="","",B7/C7*100) -> 2.88 | F7: HNX Q2 2026 announcement, rank 8 of 10
A8: HOSE listed-share brokerage | C8: 100 | D8: per cent of traded value | E8: =IF(B8="","",B8/C8*100) | F8: Not in the top ten. Tenth place held 2.94 per cent, so DNSE is below that
A9: Lending balance | B9: 6303.1 | C9: 453800 | D9: VND bn | E9: =IF(B9="","",B9/C9*100) -> 1.3889599 | F9: DNSE filed statements, 30 June 2026; industry total from Vietstock
A10: Q2 2026 pre-tax profit | B10: 97.4 | C10: ='Industry cross-section'!D16 -> 9519.4 | D10: VND bn | E10: =IF(B10="","",B10/C10*100) -> 1.0231737 | F10: DNSE: reviewed half year less Q1. Total: sum of the firms on the Industry cross-section sheet
A12: The monetisation gap
A13: Ratio | B13: Value | F13: Reading
A14: HNX trading share divided by account share | B14: =E7/E5 -> 0.23527233 | F14: An average DNSE account trades at this fraction of the value of an average market account
A15: Lending share divided by account share | B15: =E9/E5 -> 0.11346661 | F15: An average DNSE account carries this fraction of the borrowing of an average market account
A16: Derivatives share divided by account share | B16: =E6/E5 -> 2.0733374 | F16: Above one, so the derivatives franchise runs ahead of the account base

Sheet Market and macro
A1: Vietnamese market and macro series, 2018 to 2026
A2: Index levels and traded value from Vietcap's daily price service; accounts from VSDC annual reports and its homepage counter; macro from the World Bank WDI API and NSO releases. 2026 market rows run to 2026-09-24.
A4: Markets, by year
A5: Series | B5: 2018 | C5: 2019 | D5: 2020 | E5: 2021 | F5: 2022 | G5: 2023 | H5: 2024 | I5: 2025 | J5: 2026 | K5: Note
A6: VN-Index, year-end close | B6: 892.54 | C6: 960.99 | D6: 1103.87 | E6: 1498.28 | F6: 1007.09 | G6: 1129.93 | H6: 1266.78 | I6: 1784.49 | J6: 1775.09
A7: VN-Index, change on year, per cent | C7: 7.67 | D7: 14.87 | E7: 35.73 | F7: -32.78 | G7: 12.2 | H7: 12.11 | I7: 40.87 | J7: -0.53
A8: HOSE average daily traded value, VND bn | B8: 4260.1 | C8: 2936.4 | D8: 5224.7 | E8: 20084.1 | F8: 15588.1 | G8: 13548.9 | H8: 16410.1 | I8: 25150.9 | J8: 23563.5 | K8: Order matching and put-through
A9: HNX-Index, year-end close | B9: 104.23 | C9: 102.51 | D9: 203.12 | E9: 473.99 | F9: 205.31 | G9: 231.04 | H9: 227.43 | I9: 248.77 | J9: 272.77
A10: HNX average daily traded value, VND bn | B10: 709.9 | C10: 316.8 | D10: 597.5 | E10: 2903 | F10: 1760.7 | G10: 1532.7 | H10: 1306.3 | I10: 1825.1 | J10: 1368.4
A11: UPCoM-Index, year-end close | B11: 52.83 | C11: 56.56 | D11: 74.45 | E11: 112.68 | F11: 71.65 | G11: 87.04 | H11: 95.06 | I11: 121.37 | J11: 125.7
A12: UPCoM average daily traded value, VND bn | B12: 269.6 | C12: 203.7 | D12: 310.1 | E12: 1505.4 | F12: 952.6 | G12: 587.7 | H12: 742.9 | I12: 774.1 | J12: 625.1
A13: VN30 futures front month, average daily value, VND bn | B13: 7135.5 | C13: 7508.9 | D13: 12564.3 | E13: 25510.8 | F13: 31901.2 | G13: 25416 | H13: 26442.5 | I13: 39552.1 | J13: 44995.1 | K13: Contracts x close x VND 100,000; the service's own value field is unusable before July 2024
A14: DSE share price, year-end close, VND | H14: 23759.18 | I14: 23400.55 | J14: 22000 | K14: Listed on HOSE in 2024; prices adjusted
A16: Securities accounts, year end
A17: Series | B17: 2018 | C17: 2019 | D17: 2020 | E17: 2021 | F17: 2022 | G17: 2023 | H17: 2024 | I17: 2025 | J17: 2026 | K17: Note
A18: All investor accounts, VSDC | B18: 2182327 | C18: 2374894 | D18: 2771409 | E18: 4310211 | F18: 6897071 | G18: 7292361 | H18: 9297988 | I18: 11871933 | J18: 13887603 | K18: VSDC annual reports; 2026 is the homepage counter on 2026-09-24
A19: Domestic investors | B19: 2154033 | C19: 2342679 | D19: 2736338 | E19: 4270701 | F19: 6854360 | G19: 7246977 | H19: 9250208 | I19: 11821745 | K19: VSDC annual reports
A20: Foreign investors | B20: 28294 | C20: 32215 | D20: 35071 | E20: 39510 | F20: 42711 | G20: 45384 | H20: 47780 | I20: 50188 | K20: VSDC annual reports
A21: Opened during the year | B21: 276547 | C21: 213596 | D21: 401783 | F21: 2608645 | G21: 1539304 | H21: 2134838 | I21: 2681838 | K21: VSDC annual reports
A22: Growth in all accounts, per cent | C22: =IF(OR(C18="",B18=""),"",(C18/B18-1)*100) -> 8.8239297 | D22: =IF(OR(D18="",C18=""),"",(D18/C18-1)*100) -> 16.696114 | E22: =IF(OR(E18="",D18=""),"",(E18/D18-1)*100) -> 55.524176 | F22: =IF(OR(F18="",E18=""),"",(F18/E18-1)*100) -> 60.017015 | G22: =IF(OR(G18="",F18=""),"",(G18/F18-1)*100) -> 5.7312735 | H22: =IF(OR(H18="",G18=""),"",(H18/G18-1)*100) -> 27.503123 | I22: =IF(OR(I18="",H18=""),"",(I18/H18-1)*100) -> 27.682817 | J22: =IF(OR(J18="",I18=""),"",(J18/I18-1)*100) -> 16.978448 | K22: 2026 is year to date
A23: DNSE accounts | D23: 5548 | E23: 44727 | F23: 189845 | G23: 561279 | H23: 994811 | I23: 1512920 | J23: 1700000 | K23: DNSE annual report 2025, figure 22; 2026 is 30 June, company statement
A24: DNSE share of all accounts, per cent | B24: =IF(OR(B23="",B18=""),"",B23/B18*100) | C24: =IF(OR(C23="",C18=""),"",C23/C18*100) | D24: =IF(OR(D23="",D18=""),"",D23/D18*100) -> 0.20018698 | E24: =IF(OR(E23="",E18=""),"",E23/E18*100) -> 1.0376986 | F24: =IF(OR(F23="",F18=""),"",F23/F18*100) -> 2.7525452 | G24: =IF(OR(G23="",G18=""),"",G23/G18*100) -> 7.6968077 | H24: =IF(OR(H23="",H18=""),"",H23/H18*100) -> 10.699207 | I24: =IF(OR(I23="",I18=""),"",I23/I18*100) -> 12.74367 | J24: =IF(OR(J23="",J18=""),"",J23/J18*100) -> 12.241133 | K24: 2026 mixes 30 June for DNSE with September for the market
A25: DNSE share of accounts opened, per cent | C25: =IF(OR(C21="",C23="",B23=""),"",(C23-B23)/C21*100) | D25: =IF(OR(D21="",D23="",C23=""),"",(D23-C23)/D21*100) | E25: =IF(OR(E21="",E23="",D23=""),"",(E23-D23)/E21*100) | F25: =IF(OR(F21="",F23="",E23=""),"",(F23-E23)/F21*100) -> 5.5629647 | G25: =IF(OR(G21="",G23="",F23=""),"",(G23-F23)/G21*100) -> 24.129996 | H25: =IF(OR(H21="",H23="",G23=""),"",(H23-G23)/H21*100) -> 20.307489 | I25: =IF(OR(I21="",I23="",H23=""),"",(I23-H23)/I21*100) -> 19.319176 | J25: =IF(OR(J21="",J23="",I23=""),"",(J23-I23)/J21*100) | K25: Net increase in DNSE accounts over VSDC openings, so a floor on DNSE's share of gross openings
A27: Macro, World Bank WDI (last updated 2026-07-13)
A28: Indicator | B28: 2018 | C28: 2019 | D28: 2020 | E28: 2021 | F28: 2022 | G28: 2023 | H28: 2024 | I28: 2025 | J28: 2026 | K28: WDI code
A29: GDP growth, per cent | B29: 7.47 | C29: 7.36 | D29: 2.87 | E29: 2.55 | F29: 8.54 | G29: 4.98 | H29: 7.04 | I29: 8.02 | K29: NY.GDP.MKTP.KD.ZG
A30: Consumer price inflation, per cent | B30: 3.54 | C30: 2.8 | D30: 3.22 | E30: 1.83 | F30: 3.16 | G30: 3.25 | H30: 3.62 | I30: 3.31 | K30: FP.CPI.TOTL.ZG
A31: GDP per capita, current USD | B31: 3222.31 | C31: 3440.9 | D31: 3534.04 | E31: 3704.19 | F31: 4147.7 | G31: 4322.83 | H31: 4716.66 | I31: 5065.99 | K31: NY.GDP.PCAP.CD
A32: Gross savings, per cent of GDP | B32: 30.93 | C32: 31.33 | D32: 33.01 | E32: 32.6 | F32: 33.05 | G32: 35 | H32: 37.04 | K32: NY.GNS.ICTR.ZS
A33: Household consumption, per cent of GDP | B33: 57.08 | C33: 56.83 | D33: 55.97 | E33: 55.52 | F33: 54.68 | G33: 54.02 | H33: 53.56 | I33: 53.21 | K33: NE.CON.PRVT.ZS
A34: Deposit interest rate, per cent | B34: 4.74 | C34: 4.97 | D34: 4.12 | E34: 3.38 | F34: 3.82 | G34: 4.78 | K34: FR.INR.DPST
A35: Lending interest rate, per cent | B35: 7.37 | C35: 7.71 | D35: 7.65 | E35: 7.81 | F35: 8.01 | G35: 9.32 | K35: FR.INR.LEND
A36: Domestic credit to the private sector, per cent of GDP | B36: 105.28 | C36: 108.03 | D36: 115.53 | E36: 124.28 | F36: 124.96 | K36: FS.AST.PRVT.GD.ZS
A37: Broad money, per cent of GDP | B37: 124.99 | C37: 129.15 | D37: 140.6 | E37: 146.16 | F37: 136.26 | K37: FM.LBL.BMNY.GD.ZS
A38: Market capitalisation of listed companies, per cent of GDP | B38: 42.78 | C38: 44.81 | D38: 53.66 | E38: 76.07 | F38: 41.15 | G38: 43.3 | H38: 42.96 | I38: 61.4 | K38: CM.MKT.LCAP.GD.ZS
A39: Value of stocks traded, per cent of GDP | B39: 14.71 | C39: 9.44 | D39: 16.4 | E39: 51.89 | F39: 39.2 | G39: 31.43 | H39: 33.68 | I39: 43.96 | K39: CM.MKT.TRAD.GD.ZS
A40: Unemployment, per cent of labour force | B40: 1.16 | C40: 1.68 | D40: 2.1 | E40: 2.38 | F40: 1.57 | G40: 1.65 | H40: 1.6 | I40: 1.52 | K40: SL.UEM.TOTL.ZS
A41: Official exchange rate, VND per USD | B41: 22602.05 | C41: 23050.24 | D41: 23208.37 | E41: 23159.78 | F41: 23271.21 | G41: 23787.32 | H41: 24164.89 | K41: PA.NUS.FCRF
A42: Population | B42: 96237319 | C42: 97173776 | D42: 98079191 | E42: 98935098 | F42: 99680655 | G42: 100352192 | H42: 100987686 | I42: 101598527 | K42: SP.POP.TOTL
A43: Internet users, per cent of population | B43: 69.85 | C43: 68.66 | D43: 70.3 | E43: 74.21 | F43: 78.59 | G43: 78.08 | H43: 84.15 | K43: IT.NET.USER.ZS
...

Sheet Review analysis
A1: Google Play reviews: DNSE Entrade X and two competitors
A2: Collected 20 to 21 September 2026 from the public Google Play listings. The cleaning rule described below was applied identically to all three applications.
A4: Method
A5: Retrieval | B5: Google Play public review listing, paginated through the store's own continuation token. Fields captured: review id, author, star rating, text, timestamp, helpfulness votes. No authentication.
A6: Normalisation | B6: Every review text was converted to a comparable form before filtering: Unicode compatibility composition, then decomposition with combining marks removed, then lower case. The first step matters because much of the loan spam disguises itself with mathematical alphanumeric characters such as VayTotNhat, which plain keyword filters miss.
A7: Loan spam rule | B7: vay 9 | vaytotnhat | vay t?o?t nhat | ktien | vayhangdau | vay333 | vayfe | fbvay | c0m | vay 0 % | vay von 0
A8: Referral spam rule | B8: A referral phrase (nhap ma, ma gioi thieu, ma nguoi gioi thieu, ma gt, ma gth, ma moi, ma dai ly, ma vip, ma nhan thuong) within 40 characters of a code or a reward amount; or a code within 20 characters of a reward amount; or a six-digit code written against 'ma'. A code is six digits that are not a round sum or one repeated digit, or four to eight capitals and digits with at least one of each (MFBCFA only after a named referral phrase), excluding VN30 futures, index and covered-warrant codes. A phrase alone is not enough: 'nhap ma OTP' is an onboarding complaint and 'ma moi' is also 'mà mỗi'.
A9: Duplicate rule | B9: The same normalised text of 20 or more alphanumeric characters, or the same text again from the same author. The earliest copy is kept. Short texts such as 'good' recur because many people write them, so they stay in and are handled by the generic flag.
A10: Generic flag | B10: A retained review of a single word carrying no theme, for example tot, hay, ok. Counted separately rather than removed, so that a year full of one-word praise cannot be read as satisfaction. The sensitivity table below repeats the split under two- and four-word rules.
A11: Theme tags | B11: Non-exclusive whole-word keyword matches on the normalised text. Syllables that collide once tone marks are removed (lỗi/lời/lợi, lừa/lựa, sập/sắp, thưởng/thường) are matched with their accents or inside longer phrases. A review may carry several themes or none.
A12: Revision | B12: The rules were revised on 23 September 2026 after a code audit. Re-running the previous rules on the same pull reproduces the earlier published cleaning log exactly.
A13: Known limitation | B13: App store reviews are self-selected and over-represent dissatisfied users. The peer comparison mitigates this partially, because the same bias applies to all three applications. The VPS sample is its 1,200 most recent reviews, back to 2023-03-27; the listing goes back further.
A15: Cleaning log
A16: Stage | B16: DNSE | C16: VPS SmartOne | D16: FPTS EzTrade | G16: Note
A17: Reviews retrieved | B17: 867 | C17: 1200 | D17: 177 | G17: Full available history except VPS, its 1,200 most recent
A18: Loan advertising removed | B18: 127 | C18: 23 | D18: 0
A19: Referral farming removed | B19: 70 | C19: 3 | D19: 0
A20: Duplicates removed | B20: 0 | C20: 3 | D20: 0
A21: Reviews retained | B21: 670 | C21: 1171 | D21: 177
A22: Removed as a share of the pull, per cent | B22: =(B17-B21)/B17*100 -> 22.72203 | C22: =(C17-C21)/C17*100 -> 2.4166667 | D22: =(D17-D21)/D17*100 -> 0
A23: Mean rating before cleaning | B23: 3.29 | C23: 2.597 | D23: 2.181
A24: Mean rating after cleaning | B24: 3.218 | C24: 2.582 | D24: 2.181
A25: Mean rating of removed material | B25: 3.533 | C25: 3.207 | G25: Cleaning lowers the DNSE mean because the spam removed is rated more favourably than the genuine reviews left behind
A27: DNSE ratings by year
A28: Year | B28: Retrieved | C28: Removed | D28: Removed, per cent | E28: Retained | F28: Mean, retained | G28: Generic, of retained
A29: 2020 | B29: 3 | C29: 0 | D29: =C29/B29*100 -> 0 | E29: =B29-C29 -> 3 | F29: 3.667 | G29: 0
A30: 2021 | B30: 72 | C30: 8 | D30: =C30/B30*100 -> 11.111111 | E30: =B30-C30 -> 64 | F30: 2.031 | G30: 4
A31: 2022 | B31: 207 | C31: 96 | D31: =C31/B31*100 -> 46.376812 | E31: =B31-C31 -> 111 | F31: 3.18 | G31: 20
A32: 2023 | B32: 154 | C32: 83 | D32: =C32/B32*100 -> 53.896104 | E32: =B32-C32 -> 71 | F32: 2.676 | G32: 7
A33: 2024 | B33: 202 | C33: 9 | D33: =C33/B33*100 -> 4.4554455 | E33: =B33-C33 -> 193 | F33: 4.352 | G33: 65
A34: 2025 | B34: 159 | C34: 1 | D34: =C34/B34*100 -> 0.62893082 | E34: =B34-C34 -> 158 | F34: 2.646 | G34: 19
A35: 2026 | B35: 70 | C35: 0 | D35: =C35/B35*100 -> 0 | E35: =B35-C35 -> 70 | F35: 3.057 | G35: 9
A36: Total | B36: =SUM(B29:B35) -> 867 | C36: =SUM(C29:C35) -> 197 | D36: =C36/B36*100 -> 22.72203 | E36: =SUM(E29:E35) -> 670 | F36: 3.218 | G36: =SUM(G29:G35) -> 124
A38: DNSE substantive ratings by year
A39: Year | B39: Substantive reviews | C39: Mean rating | D39: Generic share of retained, per cent | G39: Reading
A40: 2020 | B40: 3 | C40: 3.667 | D40: 0
A41: 2021 | B41: 60 | C41: 1.833 | D41: 6.2
A42: 2022 | B42: 91 | C42: 2.846 | D42: 18
A43: 2023 | B43: 64 | C43: 2.422 | D43: 9.9
A44: 2024 | B44: 128 | C44: 4.148 | D44: 33.7 | G44: Highest mean of any year, and also the highest share of one-word reviews
...

Sheet Review quotes
A1: Selected DNSE reviews
A2: Fifty reviews chosen as the most upvoted within each complaint theme, plus the most upvoted substantive positive reviews. Text is Vietnamese as written, truncated to 150 characters.
A4: Review id | B4: Stars | C4: Date | D4: Helpful votes | E4: Themes | F4: Text
A5: cf18775a | B5: 1 | C5: 2025-05-24 | D5: 54 | E5: onboarding|closure | F5: Bị gài rồi, bạn nào muốn đăng kí thì phải biết 1 điều là k thể hủy đăng ký kể cả khi tài khoản chưa được duyệt cũng không hủy được, và cái đoạn chụp h
A6: e8fe4927 | B6: 1 | C6: 2021-09-23 | D6: 28 | E6: onboarding | F6: 23.09.2021 đk lúc 10h sáng chờ tới gần 13h chưa vào đc mà cứ thông báo phải đợi 1h xác thực. app này có vấn đề chắc lun, đụng tới tiền bạc mà cứ lề mề
A7: 5efad1d8 | B7: 1 | C7: 2025-07-12 | D7: 25 | E7: onboarding | F7: không quét dc nfc là sao. đăng kí mà khó thế.😅
A8: e752ae28 | B8: 1 | C8: 2025-05-31 | D8: 22 | E8: onboarding | F8: có cái mã otp mà mãi dell gửi dc
A9: ec7cd283 | B9: 1 | C9: 2025-04-17 | D9: 20 | E9: onboarding | F9: đăng ký xác thực 5 lần ko đc cứ bảo vì hình chụp bị mờ
A10: 91029c97 | B10: 2 | C10: 2025-06-02 | D10: 18 | E10: stability|money | F10: Khi nạp tiền không vào giờ giao dịch, dù tiền đã trừ ở tài khoản ngân hàng, nhưng tài khoản chứng khoán không nhận được. Liên hệ cả bộ phận CSKH thì p
A11: f95e155b | B11: 1 | C11: 2024-08-07 | D11: 18 | E11: stability|ui | F11: Từ ngày 6 đến nay chart, thông tin ....đều bị đơ mà không có bất kỳ thông nào. Cái duy nhất còn hiển thị là phần tin tức. Liên quan đến tiền mà Ad chơ
A12: d7b0e147 | B12: 1 | C12: 2025-04-08 | D12: 17 | E12: onboarding|stability | F12: mã otp bị lỗi
A13: 4b62d195 | B13: 1 | C13: 2021-08-22 | D13: 16 | E13: onboarding|stability | F13: Điện thoại CMT nét như gì cứ bảo chùi camera, ko xác thực nổi đã thế còn lỗi liên tục, ko nên tải app này
A14: 975c8060 | B14: 1 | C14: 2025-07-25 | D14: 15 | E14: stability | F14: lỗi đăng nhập ko vào được thì mất tiền 100%
A15: 564355fd | B15: 1 | C15: 2025-06-28 | D15: 50 | E15: money|promo|fraud | F15: lừa đảo thông tin sai sự thật không có vụ được 100k liền đâu phải nạp tiền vào tối thiểu 2tr mới được
A16: 940c13ed | B16: 1 | C16: 2025-01-27 | D16: 20 | E16: money | F16: Giam tiền nạp thì lẹ bán cổ phiếu ra tiền thì k cho rút muốn rút phải ứng tiền phí cực chát.
... A49: 3098e894 | B49: 5 | C49: 2025-05-08 | D49: 20 | E49: stability | F49: ko bị lag như bên ssi iboard
A50: 5529fbb6 | B50: 5 | C50: 2025-07-09 | D50: 19 | F50: Sao mãi chưa thấy tính năng gửi thông báo thế DNSE ơi? Có setting thông báo các kiểu nhưng không nhận được thông báo nào cả.
A51: 10f974fe | B51: 5 | C51: 2024-10-12 | D51: 19 | F51: có rút được tiền ko mọi người
A52: d3a9f078 | B52: 4 | C52: 2024-12-21 | D52: 18 | E52: stability | F52: tiền bán cổ phiếu về chậm quá.
A53: 2683adda | B53: 5 | C53: 2023-09-01 | D53: 18 | E53: influencer | F53: Anh chị bò và gấu là người giúp em nơi em có thể học hỏi về app cảm ơn nhiều
A54: 1e200051 | B54: 4 | C54: 2025-07-04 | D54: 17 | E54: money|influencer|ui | F54: ủng hộ kênh youtube Bò và Gấu nên cài đặt app và đầu tư. app khá tốt, mình mua bán cp chưa gặp trục trặc gì. có AI hỗ trợ (chỉ ở mức trung bình), nạp

Sheet Segment model
A1: Deriving the priority customer segment
A2: Every index cell is a formula reading from the 'Segments 2024' sheet, so editing that sheet updates this one. Both indices are unweighted means, because any weighting chosen after seeing the data would be fitted to the result.
A4: Assumption
A5: Vietnamese adults aged 15 and over, millions | B5: 80.6 | C5: General Statistics Office 2024 population structure applied to a population of 102 million
A6: Segment population shares | B6: see column H | C6: Recovered from the Findex estimates themselves: for each complementary pair, All = w x first + (1 - w) x second for every indicator, and w is the median across indicators whose halves differ by more than 5 points. The income pair comes back as its defined 40/60. See implied_share in 04_segment_model.py.
A8: Index definitions
A9: Index | B9: Indicator id | C9: Indicator | K9: Row on Segments 2024
A10: A investable surplus | B10: fin17a | C10: Saved at a bank or similar institution | K10: 29
A11: A investable surplus | B11: fin17dm | C11: Saved into an account, monthly | K11: 32
A12: A investable surplus | B12: fin8 | C12: Stores money in an account | K12: 33
A13: A investable surplus | B13: fin17e | C13: Received interest on savings in the past year | K13: 34
A14: A investable surplus | B14: fin17f | C14: Saved for old age | K14: 31
A15: A investable surplus | B15: fin24bd | C15: Could cover more than two months without income | K15: 45
A16: B digital habit | B16: dig.acc | C16: Digitally enabled account | K16: 8
A17: B digital habit | B17: con26d | C17: Uses the internet daily | K17: 52
A18: B digital habit | B18: con9a | C18: Main phone is a smartphone | K18: 51
A19: B digital habit | B19: fin25e3w | C19: In-store mobile or card payment, weekly | K19: 19
A20: B digital habit | B20: fin9b | C20: Used mobile or internet to check account balance | K20: 27
A21: B digital habit | B21: fin32.acc | C21: Received wages into an account | K21: 39
A23: Segment scores
A24: Segment | B24: Index A investable | C24: Index B digital | D24: Composite | E24: Account, per cent | F24: Saved at an institution, per cent | G24: Activation gap, points | H24: Population share, per cent | I24: Unconverted adults, millions | J24: Priority score | K24: Reading
A25: All adults | B25: =AVERAGE('Segments 2024'!D29,'Segments 2024'!D32,'Segments 2024'!D33,'Segments 2024'!D34,'Segments 2024'!D31,'Segments 2024'!D45) -> 36.84 | C25: =AVERAGE('Segments 2024'!D8,'Segments 2024'!D52,'Segments 2024'!D51,'Segments 2024'!D19,'Segments 2024'!D27,'Segments 2024'!D39) -> 59.388333 | D25: =AVERAGE(B25,C25) -> 48.114167 | E25: ='Segments 2024'!D5 -> 70.55 | F25: ='Segments 2024'!D29 -> 43.09 | G25: =E25-F25 -> 27.46 | H25: 100 | I25: =$B$5*H25/100*G25/100 -> 22.13276 | J25: =D25*I25/100 -> 10.648993 | K25: National benchmark, not a segment.
A26: Women | B26: =AVERAGE('Segments 2024'!E29,'Segments 2024'!E32,'Segments 2024'!E33,'Segments 2024'!E34,'Segments 2024'!E31,'Segments 2024'!E45) -> 38.608333 | C26: =AVERAGE('Segments 2024'!E8,'Segments 2024'!E52,'Segments 2024'!E51,'Segments 2024'!E19,'Segments 2024'!E27,'Segments 2024'!E39) -> 59.008333 | D26: =AVERAGE(B26,C26) -> 48.808333 | E26: ='Segments 2024'!E5 -> 69.88 | F26: ='Segments 2024'!E29 -> 45.07 | G26: =E26-F26 -> 24.81 | H26: 51.2 | I26: =$B$5*H26/100*G26/100 -> 10.238392 | J26: =D26*I26/100 -> 4.9971887
A27: Men | B27: =AVERAGE('Segments 2024'!F29,'Segments 2024'!F32,'Segments 2024'!F33,'Segments 2024'!F34,'Segments 2024'!F31,'Segments 2024'!F45) -> 34.986667 | C27: =AVERAGE('Segments 2024'!F8,'Segments 2024'!F52,'Segments 2024'!F51,'Segments 2024'!F19,'Segments 2024'!F27,'Segments 2024'!F39) -> 59.788333 | D27: =AVERAGE(B27,C27) -> 47.3875 | E27: ='Segments 2024'!F5 -> 71.25 | F27: ='Segments 2024'!F29 -> 41.01 | G27: =E27-F27 -> 30.24 | H27: 48.8 | I27: =$B$5*H27/100*G27/100 -> 11.894239 | J27: =D27*I27/100 -> 5.6363824
A28: Young (15-24) | B28: =AVERAGE('Segments 2024'!G29,'Segments 2024'!G32,'Segments 2024'!G33,'Segments 2024'!G34,'Segments 2024'!G31,'Segments 2024'!G45) -> 31.108333 | C28: =AVERAGE('Segments 2024'!G8,'Segments 2024'!G52,'Segments 2024'!G51,'Segments 2024'!G19,'Segments 2024'!G27,'Segments 2024'!G39) -> 66.201667 | D28: =AVERAGE(B28,C28) -> 48.655 | E28: ='Segments 2024'!G5 -> 72.16 | F28: ='Segments 2024'!G29 -> 38.58 | G28: =E28-F28 -> 33.58 | H28: 18.2 | I28: =$B$5*H28/100*G28/100 -> 4.9259174 | J28: =D28*I28/100 -> 2.3967051 | K28: Widest separation between digital habit and investable surplus, and the largest activation gap of any segment. Cheap to acquire and hard to fund.
A29: Older (25+) | B29: =AVERAGE('Segments 2024'!H29,'Segments 2024'!H32,'Segments 2024'!H33,'Segments 2024'!H34,'Segments 2024'!H31,'Segments 2024'!H45) -> 38.113333 | C29: =AVERAGE('Segments 2024'!H8,'Segments 2024'!H52,'Segments 2024'!H51,'Segments 2024'!H19,'Segments 2024'!H27,'Segments 2024'!H39) -> 57.878333 | D29: =AVERAGE(B29,C29) -> 47.995833 | E29: ='Segments 2024'!H5 -> 70.19 | F29: ='Segments 2024'!H29 -> 44.09 | G29: =E29-F29 -> 26.1 | H29: 81.8 | I29: =$B$5*H29/100*G29/100 -> 17.207939 | J29: =D29*I29/100 -> 8.2590936
A30: Primary educ or less | B30: =AVERAGE('Segments 2024'!I29,'Segments 2024'!I32,'Segments 2024'!I33,'Segments 2024'!I34,'Segments 2024'!I31,'Segments 2024'!I45) -> 15.645 | C30: =AVERAGE('Segments 2024'!I8,'Segments 2024'!I52,'Segments 2024'!I51,'Segments 2024'!I19,'Segments 2024'!I27,'Segments 2024'!I39) -> 26.51 | D30: =AVERAGE(B30,C30) -> 21.0775 | E30: ='Segments 2024'!I5 -> 33.48 | F30: ='Segments 2024'!I29 -> 13.97 | G30: =E30-F30 -> 19.51 | H30: 11.2 | I30: =$B$5*H30/100*G30/100 -> 1.7612067 | J30: =D30*I30/100 -> 0.37121835 | K30: Lowest propensity on both indices.
A31: Secondary educ or more | B31: =AVERAGE('Segments 2024'!J29,'Segments 2024'!J32,'Segments 2024'!J33,'Segments 2024'!J34,'Segments 2024'!J31,'Segments 2024'!J45) -> 39.511667 | C31: =AVERAGE('Segments 2024'!J8,'Segments 2024'!J52,'Segments 2024'!J51,'Segments 2024'!J19,'Segments 2024'!J27,'Segments 2024'!J39) -> 63.531667 | D31: =AVERAGE(B31,C31) -> 51.521667 | E31: ='Segments 2024'!J5 -> 75.22 | F31: ='Segments 2024'!J29 -> 46.71 | G31: =E31-F31 -> 28.51 | H31: 88.8 | I31: =$B$5*H31/100*G31/100 -> 20.405405 | J31: =D31*I31/100 -> 10.513205 | K31: Highest priority score, 3.9 per cent above the next.
A32: Poorest 40% | B32: =AVERAGE('Segments 2024'!K29,'Segments 2024'!K32,'Segments 2024'!K33,'Segments 2024'!K34,'Segments 2024'!K31,'Segments 2024'!K45) -> 23.128333 | C32: =AVERAGE('Segments 2024'!K8,'Segments 2024'!K52,'Segments 2024'!K51,'Segments 2024'!K19,'Segments 2024'!K27,'Segments 2024'!K39) -> 40.503333 | D32: =AVERAGE(B32,C32) -> 31.815833 | E32: ='Segments 2024'!K5 -> 48.11 | F32: ='Segments 2024'!K29 -> 27.05 | G32: =E32-F32 -> 21.06 | H32: 40 | I32: =$B$5*H32/100*G32/100 -> 6.789744 | J32: =D32*I32/100 -> 2.1602136
A33: Richest 60% | B33: =AVERAGE('Segments 2024'!L29,'Segments 2024'!L32,'Segments 2024'!L33,'Segments 2024'!L34,'Segments 2024'!L31,'Segments 2024'!L45) -> 45.966667 | C33: =AVERAGE('Segments 2024'!L8,'Segments 2024'!L52,'Segments 2024'!L51,'Segments 2024'!L19,'Segments 2024'!L27,'Segments 2024'!L39) -> 71.96 | D33: =AVERAGE(B33,C33) -> 58.963333 | E33: ='Segments 2024'!L5 -> 85.49 | F33: ='Segments 2024'!L29 -> 53.76 | G33: =E33-F33 -> 31.73 | H33: 60 | I33: =$B$5*H33/100*G33/100 -> 15.344628 | J33: =D33*I33/100 -> 9.0477042 | K33: Third-highest priority score, 9.5 per cent above the next. Highest propensity on both indices.
A34: Rural | B34: =AVERAGE('Segments 2024'!M29,'Segments 2024'!M32,'Segments 2024'!M33,'Segments 2024'!M34,'Segments 2024'!M31,'Segments 2024'!M45) -> 33.795 | C34: =AVERAGE('Segments 2024'!M8,'Segments 2024'!M52,'Segments 2024'!M51,'Segments 2024'!M19,'Segments 2024'!M27,'Segments 2024'!M39) -> 56.153333 | D34: =AVERAGE(B34,C34) -> 44.974167 | E34: ='Segments 2024'!M5 -> 67.37 | F34: ='Segments 2024'!M29 -> 40.47 | G34: =E34-F34 -> 26.9 | H34: 67 | I34: =$B$5*H34/100*G34/100 -> 14.526538 | J34: =D34*I34/100 -> 6.5331894
A35: Urban | B35: =AVERAGE('Segments 2024'!N29,'Segments 2024'!N32,'Segments 2024'!N33,'Segments 2024'!N34,'Segments 2024'!N31,'Segments 2024'!N45) -> 43.023333 | C35: =AVERAGE('Segments 2024'!N8,'Segments 2024'!N52,'Segments 2024'!N51,'Segments 2024'!N19,'Segments 2024'!N27,'Segments 2024'!N39) -> 65.961667 | D35: =AVERAGE(B35,C35) -> 54.4925 | E35: ='Segments 2024'!N5 -> 77.01 | F35: ='Segments 2024'!N29 -> 48.41 | G35: =E35-F35 -> 28.6 | H35: 33 | I35: =$B$5*H35/100*G35/100 -> 7.607028 | J35: =D35*I35/100 -> 4.1452597
