Workbook

Sheet Read me
B2: FBA Season 6 Round 2 consolidated data pack: DNSE Securities
B3: Every dataset behind the DNSE report, in one file. Compiled 20 to 21 September 2026.
B5: What this is | C5: Five datasets in one workbook. DNSE company financials and market position, the Vietnamese securities industry cross-section, 868 cleaned Google Play reviews of DNSE and two competitors, the complete Global Findex record for Vietnam, and a macro reference sheet. Every computed cell is a formula, so editing an input updates everything downstream.
B6: Where the data came from | C6: Company data from DNSE quarterly financial statements and investor relations releases. Market share from the HOSE and HNX quarterly announcements of 7 July 2026. Industry lending and profit from Q2 2026 financial statements as compiled by Vietstock and Mekong Asean. Findex from the World Bank Open Data API, source 28, country VNM, endpoint api.worldbank.org/v2/sources/28/country/VNM/series/all/data?format=json, which returned 19,878 observations of which 3,022 are non-null. Reviews from the public Google Play listings for vn.com.encapital.arrow, vn.com.vpbs.smartone and com.fpts.eztrade.
B7: How to read the colours | C7: Blue figures are inputs taken directly from a source. Green figures are links to another sheet. Black figures are formulas computed in this workbook. Yellow fill marks an assumption you may want to change. Editing a blue or yellow cell updates every black cell that depends on it.
B8: The review data | C8: 868 DNSE reviews, 1,200 VPS and 177 FPTS, collected 20 to 21 September 2026. The cleaning rule is written out in full on the 'Review analysis' sheet and was applied identically to all three applications, so the comparison is like for like. 235 DNSE reviews were removed as loan advertising, referral farming or duplicates.
B9: Survey waves covered | C9: 2011, 2014, 2017, 2022 and 2024. Note the labelling: the round usually called Global Findex 2021 is filed under 2022 for Vietnam in the World Bank API, and Vietnam's 2021 slot is empty. This workbook uses the API's own year labels. The 2024 wave was published in the Global Findex 2025 release; fieldwork ran May to December 2024.
B10: Sample | C10: 1,000 Vietnamese adults aged 15 and over, 199 variables in the underlying microdata file. All figures here are weighted population estimates, expressed as a percentage of adults aged 15+ unless the label says otherwise.
B11: The microdata | C11: This workbook holds published aggregates. The respondent-level file (1,000 rows, 199 columns) is a separate free download at microdata.worldbank.org/index.php/catalog/7998, reference VNM_2024_FINDEX_v02_M. Download that too if you want to do your own cross-tabulations.
B12: Why the segments matter | C12: Findex publishes every indicator broken down twelve ways: by sex, age band, education, income quintile group, urban or rural, and labour force status. That is a ready-made market segmentation. The 'Segments 2024' sheet is the core table.
B13: A caution on precision | C13: 1,000 respondents split twelve ways leaves small cells. Treat differences of a few percentage points as noise and say so in your report. The large gaps, 30 points and more, are real.
B14: A caution on definitions | C14: Findex says 70.6% of Vietnamese adults aged 15+ had an account in 2024. The State Bank puts payment account penetration above 89% of people aged 15+ for H1 2026. The two are directly comparable in denominator and roughly 18 points apart. Both are defensible: one counts people who report having an account when surveyed, the other counts accounts on bank systems, which includes duplicates one person holds across banks. Findex separately finds only 2.1% of adults holding an inactive account, which does not close the gap. Do not mix them in one chart without saying which is which. Naming the discrepancy is worth marks under evidence transparency.
B15: Verification | C15: Every figure on the 'Vietnam reference' sheet was re-checked against primary or Vietnamese-language sources on 20 September 2026. Twelve claims changed on review, including the small-firm credit access ladder, the biometric verification count, bank asset sizes and the brokerage market share tables. Appendix C of the accompanying report lists each one.
B16: Licence | C16: World Bank Open Data, CC BY 4.0. Cite as: World Bank, Global Findex Database 2025. Reproducing it in a student report is fine; say where it came from.
B18: Sheets in this workbook
B19: DNSE financials | C19: Quarterly and half-year revenue, profit and balance-sheet lines with computed margins and revenue mix.
B20: Market share | C20: HOSE, HNX and derivatives brokerage share for every firm in the top ten, second quarter of 2026.
B21: Industry cross-section | C21: Lending balances and pre-tax profit for the largest securities firms, with shares of the industry total.
B22: DNSE position | C22: The five share measures that define the monetisation gap, each against its own denominator.
B23: Review analysis | C23: Cleaning log, ratings by year, complaint themes and the three-app comparison.
B24: Review quotes | C24: Fifty selected reviews with rating, date, helpfulness votes and theme tags.
B25: Segment model | C25: The derived priority segment. Every index cell is a formula reading from Segments 2024.
B26: Segments 2024 | C26: 51 Findex indicators by all twelve Findex segments, latest wave.
B27: Segment gaps | C27: Computed gaps between rich and poor, urban and rural, and by education.
B28: National 2024 | C28: Indicators the World Bank publishes only at national level for 2024.
B29: Trends | C29: Headline indicators across all five survey waves, 2011 to 2024.
B30: Vietnam reference | C30: Macro, banking, payments and capital-markets figures with sources and periods.
B31: Sources | C31: Where to get everything else, with links.
B33: Findex segment codes
C34: Indicator ids ending .1 to .12 are segment cuts of the base indicator: .1 women, .2 men, .3 age 15-24, .4 age 25+, .5 primary education or less, .6 secondary or more, .7 poorest 40%, .8 richest 60%, .9 rural, .10 urban, .11 out of the labour force, .12 in the labour force. A suffix of .s means the figure is a share of a sub-population rather than of all adults.

Sheet DNSE financials
A1: DNSE Securities: reported financials
A2: VND billion unless stated. Blue cells are figures taken directly from DNSE disclosures. Black cells are formulas. Source: DNSE quarterly financial statements and investor relations releases.
A4: Line | B4: FY2025 | C4: Q1 2026 | D4: Q2 2026 | E4: H1 2026 | F4: H1 as % of FY2025 | G4: Note
A5: Operating revenue | B5: 1467 | C5: 395 | D5: 453.1 | E5: 848.2 | F5: =IF(B5=0,"",E5/B5*100) -> 57.818678 | G5: Half-year revenue of 848.2 reconciles with the two quarterly figures to within rounding.
A6: Interest on lending and receivables | B6: 555.8 | C6: 147.5 | D6: 188.6 | E6: =C6+D6 -> 336.1 | F6: =IF(B6=0,"",E6/B6*100) -> 60.471393
A7: Brokerage commissions | B7: 404 | C7: 119.5 | D7: 102.5 | E7: =C7+D7 -> 222 | F7: =IF(B7=0,"",E7/B7*100) -> 54.950495 | G7: Majority derivatives
A8: Investment income | B8: 171.4 | C8: 98.4 | D8: 95 | E8: =C8+D8 -> 193.4 | F8: =IF(B8=0,"",E8/B8*100) -> 112.83547 | G8: FVTPL and held to maturity
A9: Other revenue | B9: 335.8 | C9: 29.6 | D9: 67 | E9: =C9+D9 -> 96.6 | F9: =IF(B9=0,"",E9/B9*100) -> 28.767123 | G9: Residual of each column.
A10: Pre-tax profit | B10: 340.2 | C10: 14.2 | D10: 98.9 | E10: 113.1 | F10: =IF(B10=0,"",E10/B10*100) -> 33.24515
A11: Profit after tax | B11: 272.5 | C11: 11.3 | D11: 83 | E11: 94.3 | F11: =IF(B11=0,"",E11/B11*100) -> 34.605505
A12: Margin loans and advances, period end | B12: 5832 | C12: 5910 | D12: 6303 | E12: 6303 | F12: =IF(B12=0,"",E12/B12*100) -> 108.07613 | G12: Balance, not a flow. H1 equals the Q2 closing balance. Q2 2026 is a record for the firm.
A14: Computed ratios
A15: Ratio | B15: FY2025 | C15: Q1 2026 | D15: Q2 2026 | E15: H1 2026 | G15: Note
A16: Pre-tax profit margin, per cent | B16: =B10/B5*100 -> 23.190184 | C16: =C10/C5*100 -> 3.5949367 | D16: =D10/D5*100 -> 21.827411 | E16: =E10/E5*100 -> 13.334119 | G16: Falls from 23.2 in 2025 to 13.3 at the 2026 half year
A17: Interest on lending and receivables, share of revenue | B17: =B6/B5*100 -> 37.886844 | C17: =C6/C5*100 -> 37.341772 | D17: =D6/D5*100 -> 41.624365 | E17: =E6/E5*100 -> 39.625088
A18: Brokerage commissions, share of revenue | B18: =B7/B5*100 -> 27.539196 | C18: =C7/C5*100 -> 30.253165 | D18: =D7/D5*100 -> 22.621938 | E18: =E7/E5*100 -> 26.173072
A19: Investment income, share of revenue | B19: =B8/B5*100 -> 11.683708 | C19: =C8/C5*100 -> 24.911392 | D19: =D8/D5*100 -> 20.966674 | E19: =E8/E5*100 -> 22.801226
A21: Customers, plan and yield
A22: Item | B22: Value | C22: Unit | G22: Source or formula
A23: Customer accounts, end 2025 | B23: 1500000 | C23: accounts | G23: DNSE annual report 2025
A24: Customer accounts, Q1 2026 | B24: 1650000 | C24: accounts | G24: Q1 2026 release
A25: Customer accounts, H1 2026 | B25: 1700000 | C25: accounts | G25: H1 2026 release, stated as over 1.7 million
A26: Share of new accounts opened, 2025 | B26: 20 | C26: per cent | G26: DNSE annual report 2025
A27: Share of new accounts opened, Q1 2026 | B27: 18 | C27: per cent | G27: Q1 2026 release, 142,000 accounts
A28: 2026 revenue target | B28: 1736 | C28: VND bn | G28: 2026 annual general meeting
A29: 2026 pre-tax profit target | B29: 550 | C29: VND bn | G29: 2026 annual general meeting
A30: Charter capital | B30: 4286 | C30: VND bn | G30: 428.6 million shares
A31: Customer assets, end 2025 | B31: 52000 | C31: VND bn | G31: DNSE annual report 2025, approximate
A33: Derived measures
A34: Measure | B34: Value | G34: Definition
A35: Revenue per account, H1 2026, VND thousand | B35: =E5*1000000/B25 -> 498.94118 | G35: Half-year operating revenue divided by accounts
A36: Brokerage revenue per account, H1 2026, VND thousand | B36: =E7*1000000/B25 -> 130.58824 | G36: Half-year brokerage commissions divided by accounts
A37: Customer assets per account, end 2025, VND million | B37: =B31*1000/B23 -> 34.666667 | G37: Approximate customer assets divided by accounts
A38: Implied annual yield on lending, per cent | B38: =E6/((C12+D12)/2)*2*100 -> 11.007942 | G38: Half-year interest divided by the average of the Q1 and Q2 closing balances, annualised
A39: H1 revenue as a share of the 2026 target, per cent | B39: =E5/B28*100 -> 48.859447 | G39: Half-year pace would be 50
A40: H1 profit as a share of the 2026 target, per cent | B40: =E10/B29*100 -> 20.563636 | G40: Half-year pace would be 50
A41: Pre-tax profit still required in H2 2026, VND bn | B41: =B29-E10 -> 436.9 | G41: Target less the half-year result
A42: H2 requirement as a multiple of H1 | B42: =(B29-E10)/E10 -> 3.8629531

Sheet Market share
A1: Brokerage market share, second quarter of 2026
A2: Each percentage is a share of traded value on the named market. Shares from different markets are not comparable with one another. Sources: HOSE and HNX quarterly announcements of 7 July 2026.
A4: Firm | B4: HOSE Q2 2026 | C4: HOSE Q1 2026 | D4: HOSE change, points | E4: HNX Q2 2026 | F4: Derivatives Q2 2026 | G4: Note
A5: VPS | B5: 12.61 | C5: 15.32 | D5: =IF(OR(B5="",C5=""),"",B5-C5) -> -2.71 | E5: 17.71 | F5: 33.84 | G5: Leads every market but lost 2.71 points of HOSE share in one quarter
A6: SSI | B6: 11.17 | C6: 11.14 | D6: =IF(OR(B6="",C6=""),"",B6-C6) -> 0.03 | F6: 8.21
A7: TCBS | B7: 9.36 | C7: 8.85 | D7: =IF(OR(B7="",C7=""),"",B7-C7) -> 0.51 | E7: 9 | G7: Largest lending book in the industry
A8: Vietcap | B8: 7 | C8: 7.35 | D8: =IF(OR(B8="",C8=""),"",B8-C8) -> -0.35 | E8: 2.86
A9: HSC | B9: 6.8 | C9: 7.3 | D9: =IF(OR(B9="",C9=""),"",B9-C9) -> -0.5
A10: MBS | B10: 4.79 | C10: 5.29 | D10: =IF(OR(B10="",C10=""),"",B10-C10) -> -0.5
A11: VNDirect | B11: 3.96 | C11: 4.78 | D11: =IF(OR(B11="",C11=""),"",B11-C11) -> -0.82
A12: VPBankS | B12: 3.57 | C12: 2.94 | D12: =IF(OR(B12="",C12=""),"",B12-C12) -> 0.63 | E12: 6.71 | G12: Largest gainer of the quarter on both exchanges
A13: KIS Vietnam | B13: 2.99 | C13: 3.21 | D13: =IF(OR(B13="",C13=""),"",B13-C13) -> -0.22
A14: Mirae Asset Vietnam | B14: 2.94 | C14: 2.82 | D14: =IF(OR(B14="",C14=""),"",B14-C14) -> 0.12
A15: BSC | B15: outside top ten | E15: 3.58
A16: DNSE | B16: outside top ten | E16: 2.88 | F16: 25.38 | G16: Second in derivatives, eighth on HNX, outside the top ten on HOSE
A17: VIX | B17: outside top ten | E17: 2.66
A18: Sum of the firms listed above | B18: =SUM(B5:B17) -> 65.19 | C18: =SUM(C5:C17) -> 69 | E18: =SUM(E5:E17) -> 45.4 | F18: =SUM(F5:F17) -> 67.43 | G18: HOSE column should reconcile to the top-ten total of 65.19
A19: Published top ten total | B19: 65.19 | C19: 69.05 | E19: 63.2 | F19: 94.52 | G19: HNX and derivatives columns include only the firms whose figures were published
A22: DNSE derivatives brokerage share by quarter
A23: Quarter | B23: Share, per cent | C23: Change on previous, points | G23: Source
A24: Q1 2024 | B24: 4.01 | G24: HNX quarterly announcement
A25: Q1 2025 | B25: 16.7 | C25: =B25-B24 -> 12.69 | G25: HNX quarterly announcement
A26: Q2 2025 | B26: 17.33 | C26: =B26-B25 -> 0.63 | G26: HNX quarterly announcement
A27: Q3 2025 | B27: 23.67 | C27: =B27-B26 -> 6.34 | G27: HNX quarterly announcement
A28: Q4 2025 | B28: 24.26 | C28: =B28-B27 -> 0.59 | G28: HNX quarterly announcement
A29: Q1 2026 | B29: 25.5 | C29: =B29-B28 -> 1.24 | G29: HNX quarterly announcement
A30: Q2 2026 | B30: 25.38 | C30: =B30-B29 -> -0.12 | G30: HNX quarterly announcement

Sheet Industry cross-section
A1: Vietnamese securities industry, second quarter of 2026
A2: Lending balances and pre-tax profit from quarterly financial statements. Shares are formulas against the industry total in the assumption cell below.
A4: Firm | B4: Lending balance, VND bn | C4: Share of industry, per cent | D4: Q2 2026 pre-tax profit, VND bn | E4: HOSE brokerage share, per cent | F4: Note
A5: TCBS | B5: 51500 | C5: =IF(B5="","",B5/$B$14*100) -> 11.348612 | D5: 2097 | E5: 9.36 | F5: Year on year +21%
A6: SSI | B6: 40500 | C6: =IF(B6="","",B6/$B$14*100) -> 8.9246364 | D6: 1511 | E6: 11.17 | F6: Year on year +32%
A7: VPBankS | B7: 38200 | C7: =IF(B7="","",B7/$B$14*100) -> 8.4178052 | D7: 2159 | E7: 3.57 | F7: Year on year about four times
A8: VPS | B8: 31300 | C8: =IF(B8="","",B8/$B$14*100) -> 6.8973116 | D8: 1378 | E8: 12.61 | F8: Year on year +57%
A9: HSC | B9: 29000 | C9: =IF(B9="","",B9/$B$14*100) -> 6.3904804 | E9: 6.8
A10: DNSE | B10: 6303 | C10: =IF(B10="","",B10/$B$14*100) -> 1.3889379 | D10: 98.9 | F10: Year on year +8.7%
A11: VNDirect | C11: =IF(B11="","",B11/$B$14*100) | D11: 1100 | E11: 3.96 | F11: Year on year +127%
A12: VIX | C12: =IF(B12="","",B12/$B$14*100) | D12: 75 | F12: Year on year -95%
A13: Firms listed above | B13: =SUM(B5:B12) -> 196803 | C13: =B13/$B$14*100 -> 43.367783 | D13: =SUM(D5:D12) -> 8418.9
A14: Industry total lending | B14: 453800 | F14: The 453,800 figure is total lending, which includes advances against sale proceeds. Press estimates of margin lending alone for the same date cluster around 445,000.
A16: Previous quarter industry total | B16: 424100 | C16: =(B14-B16)/B16*100 -> 7.0030653 | F16: Quarterly growth in industry lending, per cent, reported as 7

Sheet DNSE position
A1: Where DNSE is large and where it is small
A2: Each row compares DNSE against its own denominator. The five denominators differ, so the rows measure position in five separate markets rather than five slices of one market.
A4: Measure | B4: DNSE | C4: Market total | D4: Unit | E4: DNSE share, per cent | F4: Source
A5: Customer accounts | B5: 1700000 | C5: 13852633 | D5: accounts | E5: =IF(B5="","",B5/C5*100) -> 12.272035 | F5: 13.80 million domestic individual accounts plus 52,633 foreign accounts, end August 2026, VSDC
A6: Derivatives brokerage | B6: 25.38 | C6: 100 | D6: per cent of traded value | E6: =IF(B6="","",B6/C6*100) -> 25.38 | F6: HNX Q2 2026 announcement
A7: HNX listed-share brokerage | B7: 2.88 | C7: 100 | D7: per cent of traded value | E7: =IF(B7="","",B7/C7*100) -> 2.88 | F7: HNX Q2 2026 announcement, rank 8 of 10
A8: HOSE listed-share brokerage | C8: 100 | D8: per cent of traded value | E8: =IF(B8="","",B8/C8*100) | F8: Not in the top ten. Tenth place held 2.94 per cent, so DNSE is below that
A9: Lending balance | B9: 6303 | C9: 453800 | D9: VND bn | E9: =IF(B9="","",B9/C9*100) -> 1.3889379 | F9: Q2 2026 financial statements, industry total from Vietstock
A10: Q2 2026 pre-tax profit | B10: 98.9 | C10: 9977 | D10: VND bn | E10: =IF(B10="","",B10/C10*100) -> 0.99127994 | F10: Sum of the firms on the Industry cross-section sheet
A12: The monetisation gap
A13: Ratio | B13: Value | F13: Reading
A14: HNX trading share divided by account share | B14: =E7/E5 -> 0.2346799 | F14: An average DNSE account trades at this fraction of the value of an average market account
A15: Lending share divided by account share | B15: =E9/E5 -> 0.1131791 | F15: An average DNSE account carries this fraction of the borrowing of an average market account
A16: Derivatives share divided by account share | B16: =E6/E5 -> 2.0681166 | F16: Above one, so the derivatives franchise runs ahead of the account base

Sheet Review analysis
A1: Google Play reviews: DNSE Entrade X and two competitors
A2: Collected 20 to 21 September 2026 from the public Google Play listings. The cleaning rule described below was applied identically to all three applications.
A4: Method
A5: Retrieval | B5: Google Play public review listing, paginated through the store's own continuation token. Fields captured: review id, author, star rating, text, timestamp, helpfulness votes. No authentication.
A6: Normalisation | B6: Every review text was converted to a comparable form before filtering: Unicode compatibility composition, then decomposition with combining marks removed, then lower case. The first step matters because much of the loan spam disguises itself with mathematical alphanumeric characters such as VayTotNhat, which plain keyword filters miss.
A7: Loan spam rule | B7: vay 9 | vaytotnhat | vay t?o?t nhat | ktien | vayhangdau | vay333 | vayfe | fbvay | c0m | .com | vay 0 % | vay von 0
A8: Referral spam rule | B8: ma (gioi thieu | gt | moi | dai ly) | nhap ma | ref(erral)? id | ma + five or more digits | six digits followed by nhan or ma
A9: Duplicate rule | B9: Identical alphanumeric-only normalised text. Second and later copies removed. Texts under four characters are exempt.
A10: Generic flag | B10: A retained review of four words or fewer carrying no theme, for example tot, hay, ok. Counted separately rather than removed, so that a year full of one-word praise cannot be read as satisfaction.
A11: Theme tags | B11: Non-exclusive keyword matches on the normalised text. A review may carry several themes or none.
A12: Known limitation | B12: App store reviews are self-selected and over-represent dissatisfied users. The peer comparison mitigates this partially, because the same bias applies to all three applications. The VPS sample is capped at 1,200 by pagination and is truncated toward recent reviews.
A14: Cleaning log
A15: Stage | B15: DNSE | C15: VPS SmartOne | D15: FPTS EzTrade | G15: Note
A16: Reviews retrieved | B16: 868 | C16: 1200 | D16: 177 | G16: Full available history except VPS, capped by pagination
A17: Loan advertising removed | B17: 127
A18: Referral farming removed | B18: 72
A19: Duplicates removed | B19: 36
A20: Reviews retained | B20: 633 | C20: 1116 | D20: 169 | G20: DNSE loses 27.1 per cent, VPS 7.0, FPTS 4.5
A21: Removed as a share of the pull, per cent | B21: =(B16-B20)/B16*100 -> 27.073733 | C21: =(C16-C20)/C16*100 -> 7 | D21: =(D16-D20)/D16*100 -> 4.519774
A22: Mean rating before cleaning | B22: 3.287 | C22: 2.597 | D22: 2.181
A23: Mean rating after cleaning | B23: 3.161 | C23: 2.515 | D23: 2.154
A24: Mean rating of removed material | B24: 3.626 | G24: Cleaning lowers the DNSE mean because the spam removed is rated more favourably than the genuine reviews left behind
A26: DNSE ratings by year
A27: Year | B27: Retrieved | C27: Removed | D27: Removed, per cent | E27: Retained | F27: Mean, retained | G27: Generic, of retained
A28: 2020 | B28: 3 | C28: 0 | D28: =C28/B28*100 -> 0 | E28: =B28-C28 -> 3 | F28: 3.667 | G28: 0
A29: 2021 | B29: 72 | C29: 13 | D29: =C29/B29*100 -> 18.055556 | E29: =B29-C29 -> 59 | F29: 1.983 | G29: 2
A30: 2022 | B30: 207 | C30: 101 | D30: =C30/B30*100 -> 48.792271 | E30: =B30-C30 -> 106 | F30: 3.142 | G30: 19
A31: 2023 | B31: 154 | C31: 86 | D31: =C31/B31*100 -> 55.844156 | E31: =B31-C31 -> 68 | F31: 2.574 | G31: 6
A32: 2024 | B32: 202 | C32: 27 | D32: =C32/B32*100 -> 13.366337 | E32: =B32-C32 -> 175 | F32: 4.291 | G32: 54
A33: 2025 | B33: 159 | C33: 7 | D33: =C33/B33*100 -> 4.4025157 | E33: =B33-C33 -> 152 | F33: 2.632 | G33: 20
A34: 2026 | B34: 71 | C34: 1 | D34: =C34/B34*100 -> 1.4084507 | E34: =B34-C34 -> 70 | F34: 3.057 | G34: 9
A35: Total | B35: =SUM(B28:B34) -> 868 | C35: =SUM(C28:C34) -> 235 | D35: =C35/B35*100 -> 27.073733 | E35: =SUM(E28:E34) -> 633 | F35: 3.161 | G35: =SUM(G28:G34) -> 110
A37: DNSE substantive ratings by year
A38: Year | B38: Substantive reviews | C38: Mean rating | D38: Generic share of retained, per cent | G38: Reading
A39: 2020 | B39: 3 | C39: 3.667 | D39: 0
A40: 2021 | B40: 57 | C40: 1.877 | D40: 3.4
A41: 2022 | B41: 87 | C41: 2.851 | D41: 17.9
A42: 2023 | B42: 62 | C42: 2.403 | D42: 8.8
A43: 2024 | B43: 121 | C43: 4.066 | D43: 30.9 | G43: Highest mean of any year, and also the highest share of one-word reviews
A44: 2025 | B44: 132 | C44: 2.364 | D44: 13.2 | G44: Substantive rating falls by 1.70 stars on a larger sample
...

Sheet Review quotes
A1: Selected DNSE reviews
A2: Fifty reviews chosen as the most upvoted within each complaint theme, plus the most upvoted substantive positive reviews. Text is Vietnamese as written, truncated to 150 characters.
A4: Review id | B4: Stars | C4: Date | D4: Helpful votes | E4: Themes | F4: Text
A5: cf18775a | B5: 1 | C5: 2025-05-24 | D5: 54 | E5: onboarding|closure | F5: Bị gài rồi, bạn nào muốn đăng kí thì phải biết 1 điều là k thể hủy đăng ký kể cả khi tài khoản chưa được duyệt cũng không hủy được, và cái đoạn chụp h
A6: e8fe4927 | B6: 1 | C6: 2021-09-23 | D6: 28 | E6: onboarding | F6: 23.09.2021 đk lúc 10h sáng chờ tới gần 13h chưa vào đc mà cứ thông báo phải đợi 1h xác thực. app này có vấn đề chắc lun, đụng tới tiền bạc mà cứ lề mề
A7: 5efad1d8 | B7: 1 | C7: 2025-07-12 | D7: 25 | E7: onboarding | F7: không quét dc nfc là sao. đăng kí mà khó thế.
A8: e752ae28 | B8: 1 | C8: 2025-05-31 | D8: 22 | E8: onboarding | F8: có cái mã otp mà mãi dell gửi dc
A9: ec7cd283 | B9: 1 | C9: 2025-04-17 | D9: 20 | E9: onboarding | F9: đăng ký xác thực 5 lần ko đc cứ bảo vì hình chụp bị mờ
A10: 91029c97 | B10: 2 | C10: 2025-06-02 | D10: 18 | E10: stability|money | F10: Khi nạp tiền không vào giờ giao dịch, dù tiền đã trừ ở tài khoản ngân hàng, nhưng tài khoản chứng khoán không nhận được. Liên hệ cả bộ phận CSKH thì p
A11: f95e155b | B11: 1 | C11: 2024-08-07 | D11: 18 | E11: stability | F11: Từ ngày 6 đến nay chart, thông tin đều bị đơ mà không có bất kỳ thông báo nào. Cái duy nhất còn hiển thị là phần tin tức. Liên quan đến tiền mà Ad chơi
A12: d7b0e147 | B12: 1 | C12: 2025-04-08 | D12: 17 | E12: onboarding|stability | F12: mã otp bị lỗi
A13: 4b62d195 | B13: 1 | C13: 2021-08-22 | D13: 16 | E13: onboarding|stability | F13: Điện thoại CMT nét như gì cứ bảo chùi camera, ko xác thực nổi đã thế còn lỗi liên tục, ko nên tải app này
A14: 975c8060 | B14: 1 | C14: 2025-07-25 | D14: 15 | E14: stability | F14: lỗi đăng nhập ko vào được thì mất tiền 100%
A15: 564355fd | B15: 1 | C15: 2025-06-28 | D15: 50 | E15: money|promo|fraud | F15: lừa đảo thông tin sai sự thật không có vụ được 100k liền đâu phải nạp tiền vào tối thiểu 2tr mới được
A16: 940c13ed | B16: 1 | C16: 2025-01-27 | D16: 20 | E16: money | F16: Giam tiền nạp thì lẹ bán cổ phiếu ra tiền thì k cho rút muốn rút phải ứng tiền phí cực chát.
... A46: 4094bad4 | B46: 5 | C46: 2025-05-04 | D46: 31 | E46: stability|ui | F46: Giao diện đơn giản, thuận tiện, phí thấp
A47: 06c66fa6 | B47: 4 | C47: 2025-05-04 | D47: 24 | F47: mong muốn che số dư, khối lượng như vps
A48: a018878c | B48: 5 | C48: 2024-11-13 | D48: 24 | E48: money|promo|influencer | F48: mình đã quá chán nản khuyến nghị của các broker ít kinh nghiệm thì tìm thấy dnse, khuyến nghị của app khá ok với nhà đầu tư nhỏ lẻ, ít kinh nghiệm
A49: 3098e894 | B49: 5 | C49: 2025-05-08 | D49: 20 | E49: stability | F49: ko bị lag như bên ssi iboard
A50: 5529fbb6 | B50: 5 | C50: 2025-07-09 | D50: 19 | F50: Sao mãi chưa thấy tính năng gửi thông báo thế DNSE ơi? Có setting thông báo các kiểu nhưng không nhận được thông báo nào cả.
A51: 10f974fe | B51: 5 | C51: 2024-10-12 | D51: 19 | F51: có rút được tiền ko mọi người
A52: d3a9f078 | B52: 4 | C52: 2024-12-21 | D52: 18 | E52: stability | F52: tiền bán cổ phiếu về chậm quá.
A53: 2683adda | B53: 5 | C53: 2023-09-01 | D53: 18 | E53: influencer | F53: Anh chị bò và gấu là người giúp em nơi em có thể học hỏi về app cảm ơn nhiều
A54: 1e200051 | B54: 4 | C54: 2025-07-04 | D54: 17 | E54: stability|money|influencer|ui | F54: ủng hộ kênh youtube Bò và Gấu nên cài đặt app và đầu tư. app khá tốt, mình mua bán cp chưa gặp trục trặc gì. có AI hỗ trợ (chỉ ở mức trung bình)

Sheet Segment model
A1: Deriving the priority customer segment
A2: Every index cell is a formula reading from the 'Segments 2024' sheet, so editing that sheet updates this one. Both indices are unweighted means, because any weighting chosen after seeing the data would be fitted to the result.
A4: Assumption
A5: Vietnamese adults aged 15 and over, millions | B5: 80.6 | C5: General Statistics Office 2024 population structure applied to a population of 102 million
A7: Index definitions
A8: Index | B8: Indicator id | C8: Indicator | K8: Row on Segments 2024
A9: A investable surplus | B9: fin17a | C9: Saved at a bank or similar institution | K9: 29
A10: A investable surplus | B10: fin17dm | C10: Saved into an account, monthly | K10: 32
A11: A investable surplus | B11: fin8 | C11: Stores money in an account | K11: 33
A12: A investable surplus | B12: fin17e | C12: Received interest on savings in the past year | K12: 34
A13: A investable surplus | B13: fin17f | C13: Saved for old age | K13: 31
A14: A investable surplus | B14: fin24bd | C14: Could cover more than two months without income | K14: 45
A15: B digital habit | B15: dig.acc | C15: Digitally enabled account | K15: 8
A16: B digital habit | B16: con26d | C16: Uses the internet daily | K16: 52
A17: B digital habit | B17: con9a | C17: Main phone is a smartphone | K17: 51
A18: B digital habit | B18: fin25e3w | C18: In-store mobile or card payment, weekly | K18: 19
A19: B digital habit | B19: fin9b | C19: Used mobile or internet to check account balance | K19: 27
A20: B digital habit | B20: fin32.acc | C20: Received wages into an account | K20: 39
A22: Segment scores
A23: Segment | B23: Index A investable | C23: Index B digital | D23: Composite | E23: Account, per cent | F23: Saved at an institution, per cent | G23: Activation gap, points | H23: Population share, per cent | I23: Unconverted adults, millions | J23: Priority score | K23: Reading
A24: All adults | B24: =AVERAGE('Segments 2024'!D29,'Segments 2024'!D32,'Segments 2024'!D33,'Segments 2024'!D34,'Segments 2024'!D31,'Segments 2024'!D45) -> 36.84 | C24: =AVERAGE('Segments 2024'!D8,'Segments 2024'!D52,'Segments 2024'!D51,'Segments 2024'!D19,'Segments 2024'!D27,'Segments 2024'!D39) -> 59.388333 | D24: =AVERAGE(B24,C24) -> 48.114167 | E24: ='Segments 2024'!D5 -> 70.55 | F24: ='Segments 2024'!D29 -> 43.09 | G24: =E24-F24 -> 27.46 | H24: 100 | I24: =$B$5*H24/100*G24/100 -> 22.13276 | J24: =D24*I24/100 -> 10.648993 | K24: National benchmark, not a segment.
A25: Women | B25: =AVERAGE('Segments 2024'!E29,'Segments 2024'!E32,'Segments 2024'!E33,'Segments 2024'!E34,'Segments 2024'!E31,'Segments 2024'!E45) -> 38.608333 | C25: =AVERAGE('Segments 2024'!E8,'Segments 2024'!E52,'Segments 2024'!E51,'Segments 2024'!E19,'Segments 2024'!E27,'Segments 2024'!E39) -> 59.008333 | D25: =AVERAGE(B25,C25) -> 48.808333 | E25: ='Segments 2024'!E5 -> 69.88 | F25: ='Segments 2024'!E29 -> 45.07 | G25: =E25-F25 -> 24.81 | H25: 50.9 | I25: =$B$5*H25/100*G25/100 -> 10.178402 | J25: =D25*I25/100 -> 4.9679082
A26: Men | B26: =AVERAGE('Segments 2024'!F29,'Segments 2024'!F32,'Segments 2024'!F33,'Segments 2024'!F34,'Segments 2024'!F31,'Segments 2024'!F45) -> 34.986667 | C26: =AVERAGE('Segments 2024'!F8,'Segments 2024'!F52,'Segments 2024'!F51,'Segments 2024'!F19,'Segments 2024'!F27,'Segments 2024'!F39) -> 59.788333 | D26: =AVERAGE(B26,C26) -> 47.3875 | E26: ='Segments 2024'!F5 -> 71.25 | F26: ='Segments 2024'!F29 -> 41.01 | G26: =E26-F26 -> 30.24 | H26: 49.1 | I26: =$B$5*H26/100*G26/100 -> 11.967359 | J26: =D26*I26/100 -> 5.6710323
A27: Young (15-24) | B27: =AVERAGE('Segments 2024'!G29,'Segments 2024'!G32,'Segments 2024'!G33,'Segments 2024'!G34,'Segments 2024'!G31,'Segments 2024'!G45) -> 31.108333 | C27: =AVERAGE('Segments 2024'!G8,'Segments 2024'!G52,'Segments 2024'!G51,'Segments 2024'!G19,'Segments 2024'!G27,'Segments 2024'!G39) -> 66.201667 | D27: =AVERAGE(B27,C27) -> 48.655 | E27: ='Segments 2024'!G5 -> 72.16 | F27: ='Segments 2024'!G29 -> 38.58 | G27: =E27-F27 -> 33.58 | H27: 17.1 | I27: =$B$5*H27/100*G27/100 -> 4.6281971 | J27: =D27*I27/100 -> 2.2518493 | K27: Widest separation between digital habit and investable surplus, and the largest activation gap of any segment. Cheap to acquire and hard to fund.
A28: Older (25+) | B28: =AVERAGE('Segments 2024'!H29,'Segments 2024'!H32,'Segments 2024'!H33,'Segments 2024'!H34,'Segments 2024'!H31,'Segments 2024'!H45) -> 38.113333 | C28: =AVERAGE('Segments 2024'!H8,'Segments 2024'!H52,'Segments 2024'!H51,'Segments 2024'!H19,'Segments 2024'!H27,'Segments 2024'!H39) -> 57.878333 | D28: =AVERAGE(B28,C28) -> 47.995833 | E28: ='Segments 2024'!H5 -> 70.19 | F28: ='Segments 2024'!H29 -> 44.09 | G28: =E28-F28 -> 26.1 | H28: 82.9 | I28: =$B$5*H28/100*G28/100 -> 17.439341 | J28: =D28*I28/100 -> 8.3701572
A29: Primary educ or less | B29: =AVERAGE('Segments 2024'!I29,'Segments 2024'!I32,'Segments 2024'!I33,'Segments 2024'!I34,'Segments 2024'!I31,'Segments 2024'!I45) -> 15.645 | C29: =AVERAGE('Segments 2024'!I8,'Segments 2024'!I52,'Segments 2024'!I51,'Segments 2024'!I19,'Segments 2024'!I27,'Segments 2024'!I39) -> 26.51 | D29: =AVERAGE(B29,C29) -> 21.0775 | E29: ='Segments 2024'!I5 -> 33.48 | F29: ='Segments 2024'!I29 -> 13.97 | G29: =E29-F29 -> 19.51 | H29: 23.6 | I29: =$B$5*H29/100*G29/100 -> 3.7111142 | J29: =D29*I29/100 -> 0.78221009
A30: Secondary educ or more | B30: =AVERAGE('Segments 2024'!J29,'Segments 2024'!J32,'Segments 2024'!J33,'Segments 2024'!J34,'Segments 2024'!J31,'Segments 2024'!J45) -> 39.511667 | C30: =AVERAGE('Segments 2024'!J8,'Segments 2024'!J52,'Segments 2024'!J51,'Segments 2024'!J19,'Segments 2024'!J27,'Segments 2024'!J39) -> 63.531667 | D30: =AVERAGE(B30,C30) -> 51.521667 | E30: ='Segments 2024'!J5 -> 75.22 | F30: ='Segments 2024'!J29 -> 46.71 | G30: =E30-F30 -> 28.51 | H30: 76.4 | I30: =$B$5*H30/100*G30/100 -> 17.556002 | J30: =D30*I30/100 -> 9.0451447 | K30: Effectively tied with the richest 60 per cent.
A31: Poorest 40% | B31: =AVERAGE('Segments 2024'!K29,'Segments 2024'!K32,'Segments 2024'!K33,'Segments 2024'!K34,'Segments 2024'!K31,'Segments 2024'!K45) -> 23.128333 | C31: =AVERAGE('Segments 2024'!K8,'Segments 2024'!K52,'Segments 2024'!K51,'Segments 2024'!K19,'Segments 2024'!K27,'Segments 2024'!K39) -> 40.503333 | D31: =AVERAGE(B31,C31) -> 31.815833 | E31: ='Segments 2024'!K5 -> 48.11 | F31: ='Segments 2024'!K29 -> 27.05 | G31: =E31-F31 -> 21.06 | H31: 40 | I31: =$B$5*H31/100*G31/100 -> 6.789744 | J31: =D31*I31/100 -> 2.1602136 | K31: Lowest propensity on both indices.
A32: Richest 60% | B32: =AVERAGE('Segments 2024'!L29,'Segments 2024'!L32,'Segments 2024'!L33,'Segments 2024'!L34,'Segments 2024'!L31,'Segments 2024'!L45) -> 45.966667 | C32: =AVERAGE('Segments 2024'!L8,'Segments 2024'!L52,'Segments 2024'!L51,'Segments 2024'!L19,'Segments 2024'!L27,'Segments 2024'!L39) -> 71.96 | D32: =AVERAGE(B32,C32) -> 58.963333 | E32: ='Segments 2024'!L5 -> 85.49 | F32: ='Segments 2024'!L29 -> 53.76 | G32: =E32-F32 -> 31.73 | H32: 60 | I32: =$B$5*H32/100*G32/100 -> 15.344628 | J32: =D32*I32/100 -> 9.0477042 | K32: Highest propensity on both indices. Second on priority score.
A33: Rural | B33: =AVERAGE('Segments 2024'!M29,'Segments 2024'!M32,'Segments 2024'!M33,'Segments 2024'!M34,'Segments 2024'!M31,'Segments 2024'!M45) -> 33.795 | C33: =AVERAGE('Segments 2024'!M8,'Segments 2024'!M52,'Segments 2024'!M51,'Segments 2024'!M19,'Segments 2024'!M27,'Segments 2024'!M39) -> 56.153333 | D33: =AVERAGE(B33,C33) -> 44.974167 | E33: ='Segments 2024'!M5 -> 67.37 | F33: ='Segments 2024'!M29 -> 40.47 | G33: =E33-F33 -> 26.9 | H33: 62 | I33: =$B$5*H33/100*G33/100 -> 13.442468 | J33: =D33*I33/100 -> 6.045638
A34: Urban | B34: =AVERAGE('Segments 2024'!N29,'Segments 2024'!N32,'Segments 2024'!N33,'Segments 2024'!N34,'Segments 2024'!N31,'Segments 2024'!N45) -> 43.023333 | C34: =AVERAGE('Segments 2024'!N8,'Segments 2024'!N52,'Segments 2024'!N51,'Segments 2024'!N19,'Segments 2024'!N27,'Segments 2024'!N39) -> 65.961667 | D34: =AVERAGE(B34,C34) -> 54.4925 | E34: ='Segments 2024'!N5 -> 77.01 | F34: ='Segments 2024'!N29 -> 48.41 | G34: =E34-F34 -> 28.6 | H34: 38 | I34: =$B$5*H34/100*G34/100 -> 8.759608 | J34: =D34*I34/100 -> 4.7733294
A35: Out of labour force | B35: =AVERAGE('Segments 2024'!O29,'Segments 2024'!O32,'Segments 2024'!O33,'Segments 2024'!O34,'Segments 2024'!O31,'Segments 2024'!O45) -> 18.448333 | C35: =AVERAGE('Segments 2024'!O8,'Segments 2024'!O52,'Segments 2024'!O51,'Segments 2024'!O19,'Segments 2024'!O27,'Segments 2024'!O39) -> 36.613333 | D35: =AVERAGE(B35,C35) -> 27.530833 | E35: ='Segments 2024'!O5 -> 41.31 | F35: ='Segments 2024'!O29 -> 21.95 | G35: =E35-F35 -> 19.36 | H35: 26.5 | I35: =$B$5*H35/100*G35/100 -> 4.1351024 | J35: =D35*I35/100 -> 1.1384281
A36: In labour force | B36: =AVERAGE('Segments 2024'!P29,'Segments 2024'!P32,'Segments 2024'!P33,'Segments 2024'!P34,'Segments 2024'!P31,'Segments 2024'!P45) -> 41.453333 | C36: =AVERAGE('Segments 2024'!P8,'Segments 2024'!P52,'Segments 2024'!P51,'Segments 2024'!P19,'Segments 2024'!P27,'Segments 2024'!P39) -> 65.103333 | D36: =AVERAGE(B36,C36) -> 53.278333 | E36: ='Segments 2024'!P5 -> 77.89 | F36: ='Segments 2024'!P29 -> 48.39 | G36: =E36-F36 -> 29.5 | H36: 73.5 | I36: =$B$5*H36/100*G36/100 -> 17.476095 | J36: =D36*I36/100 -> 9.3109721 | K36: Highest priority score. Largest unconverted pool at a high propensity.
A38: Spread, Index B less Index A | B38: =SUMPRODUCT(MAX(C25:C36-B25:B36)) -> 35.093333 | C38: Array formula. The widest spread belongs to adults aged 15 to 24.

Sheet Segments 2024
A1: Vietnam Findex 2024: indicators by segment
A2: Percentage of adults aged 15+ in each segment. Source: World Bank Global Findex Database 2025, retrieved via the World Bank API, 20 September 2026.
A4: Indicator id | B4: Indicator | C4: Theme | D4: All adults | E4: Women | F4: Men | G4: Young (15-24) | H4: Older (25+) | I4: Primary educ or less | J4: Secondary educ or more | K4: Poorest 40% | L4: Richest 60% | M4: Rural | N4: Urban | O4: Out of labour force | P4: In labour force
A5: account.t.d | B5: Has an account (any) | C5: Access | D5: 70.55 | E5: 69.88 | F5: 71.25 | G5: 72.16 | H5: 70.19 | I5: 33.48 | J5: 75.22 | K5: 48.11 | L5: 85.49 | M5: 67.37 | N5: 77.01 | O5: 41.31 | P5: 77.89
A6: fiaccount.t.d | B6: Bank or similar institution account | C6: Access | D6: 69.85 | E6: 69.42 | F6: 70.31 | G6: 70.58 | H6: 69.69 | I6: 33.15 | J6: 74.48 | K6: 47.66 | L6: 84.63 | M6: 66.46 | N6: 76.75 | O6: 40.73 | P6: 77.16
A7: mobileaccount.t.d | B7: Mobile money account | C7: Access | D7: 38.72 | E7: 37.02 | F7: 40.51 | G7: 51.53 | H7: 35.88 | I7: 11.52 | J7: 42.21 | K7: 22.32 | L7: 49.64 | M7: 36.19 | N7: 43.86 | O7: 18.2 | P7: 43.87
A8: dig.acc | B8: Digitally enabled account | C8: Access | D8: 62.74 | E8: 62.39 | F8: 63.11 | G8: 71.06 | H8: 60.89 | I8: 19.75 | J8: 68.14 | K8: 37.58 | L8: 79.49 | M8: 59.3 | N8: 69.73 | O8: 31.32 | P8: 70.62
A9: fin2.t.d | B9: Owns a debit card | C9: Access | D9: 64.82 | E9: 63.65 | F9: 66.04 | G9: 64.68 | H9: 64.85 | I9: 26.4 | J9: 69.65 | K9: 42.18 | L9: 79.89 | M9: 60.46 | N9: 73.67 | O9: 31.94 | P9: 73.07
A10: fin4.d | B10: First account opened to receive wages or government money | C10: Access | D10: 43.49 | E10: 42.07 | F10: 44.98 | G10: 36.75 | H10: 44.99 | I10: 19.22 | J10: 46.51 | K10: 26.52 | L10: 54.79 | M10: 39.34 | N10: 51.94 | O10: 16.04 | P10: 50.38
A11: fin11e | B11: No account: family member already has one | C11: Access | D11: 16.51 | E11: 18.82 | F11: 14.09 | G11: 20.05 | H11: 15.73 | I11: 27.98 | J11: 15.04 | K11: 26.14 | L11: 10.1 | M11: 17.87 | N11: 13.75 | O11: 33.56 | P11: 12.23
A12: fin11_2a | B12: Could use an account without help if opened | C12: Access | D12: 21.13 | E12: 22.13 | F12: 20.08 | G12: 10.89 | H12: 23.41 | I12: 53.72 | J12: 17.01 | K12: 37.18 | L12: 10.45 | M12: 21.82 | N12: 19.73 | O12: 37.18 | P12: 17.11
A13: g20.any | B13: Made or received a digital payment | C13: Digital payments | D13: 62.38 | E13: 61.4 | F13: 63.4 | G13: 66.59 | H13: 61.44 | I13: 26.47 | J13: 66.89 | K13: 38.59 | L13: 78.21 | M13: 59.52 | N13: 68.19 | O13: 30.94 | P13: 70.27
A14: g20.made | B14: Made a digital payment | C14: Digital payments | D14: 56.47 | E14: 56.53 | F14: 56.41 | G14: 63.18 | H14: 54.98 | I14: 16.58 | J14: 61.47 | K14: 31.13 | L14: 73.34 | M14: 54.16 | N14: 61.16 | O14: 25.05 | P14: 64.36
A15: g20.received | B15: Received digital payments | C15: Digital payments | D15: 48.05 | E15: 46.29 | F15: 49.89 | G15: 47.11 | H15: 48.26 | I15: 17.26 | J15: 51.89 | K15: 27.14 | L15: 61.97 | M15: 44.69 | N15: 54.88 | O15: 17.24 | P15: 55.78
A16: fin3 | B16: Used a card or mobile phone to make payments | C16: Digital payments | D16: 60.68 | E16: 60.44 | F16: 60.93 | G16: 66.97 | H16: 59.28 | I16: 17.84 | J16: 66.17 | K16: 36.07 | L16: 77.05 | M16: 57.07 | N16: 67.99 | O16: 28.79 | P16: 68.68
... A55: con30f | B55: Used apps or websites to earn money | C55: Connectivity | D55: 11.76 | E55: 12.2 | F55: 11.3 | G55: 17.61 | H55: 10.46 | I55: 2.98 | J55: 12.88 | K55: 6.4 | L55: 15.33 | M55: 8.84 | N55: 17.69 | O55: 7.79 | P55: 12.76

Sheet Segment gaps
A1: Where the segment gaps are widest
A2: Every figure is a formula referencing 'Segments 2024', so edits there flow through. Gaps are in percentage points.
A4: Indicator | B4: Theme | C4: All adults | D4: Income gap (richest 60% less poorest 40%) | E4: Education gap (secondary+ less primary or less) | F4: Urban less rural | G4: Men less women | H4: Young less older | I4: In work less out of work
A5: Has an account (any) | B5: Access | C5: ='Segments 2024'!D5 -> 70.55 | D5: ='Segments 2024'!L5-'Segments 2024'!K5 -> 37.38 | E5: ='Segments 2024'!J5-'Segments 2024'!I5 -> 41.74 | F5: ='Segments 2024'!N5-'Segments 2024'!M5 -> 9.64 | G5: ='Segments 2024'!F5-'Segments 2024'!E5 -> 1.37 | H5: ='Segments 2024'!G5-'Segments 2024'!H5 -> 1.97 | I5: ='Segments 2024'!P5-'Segments 2024'!O5 -> 36.58
A6: Bank or similar institution account | B6: Access | C6: ='Segments 2024'!D6 -> 69.85 | D6: ='Segments 2024'!L6-'Segments 2024'!K6 -> 36.97 | E6: ='Segments 2024'!J6-'Segments 2024'!I6 -> 41.33 | F6: ='Segments 2024'!N6-'Segments 2024'!M6 -> 10.29 | G6: ='Segments 2024'!F6-'Segments 2024'!E6 -> 0.89 | H6: ='Segments 2024'!G6-'Segments 2024'!H6 -> 0.89 | I6: ='Segments 2024'!P6-'Segments 2024'!O6 -> 36.43
A7: Mobile money account | B7: Access | C7: ='Segments 2024'!D7 -> 38.72 | D7: ='Segments 2024'!L7-'Segments 2024'!K7 -> 27.32 | E7: ='Segments 2024'!J7-'Segments 2024'!I7 -> 30.69 | F7: ='Segments 2024'!N7-'Segments 2024'!M7 -> 7.67 | G7: ='Segments 2024'!F7-'Segments 2024'!E7 -> 3.49 | H7: ='Segments 2024'!G7-'Segments 2024'!H7 -> 15.65 | I7: ='Segments 2024'!P7-'Segments 2024'!O7 -> 25.67
A8: Digitally enabled account | B8: Access | C8: ='Segments 2024'!D8 -> 62.74 | D8: ='Segments 2024'!L8-'Segments 2024'!K8 -> 41.91 | E8: ='Segments 2024'!J8-'Segments 2024'!I8 -> 48.39 | F8: ='Segments 2024'!N8-'Segments 2024'!M8 -> 10.43 | G8: ='Segments 2024'!F8-'Segments 2024'!E8 -> 0.72 | H8: ='Segments 2024'!G8-'Segments 2024'!H8 -> 10.17 | I8: ='Segments 2024'!P8-'Segments 2024'!O8 -> 39.3
A9: Owns a debit card | B9: Access | C9: ='Segments 2024'!D9 -> 64.82 | D9: ='Segments 2024'!L9-'Segments 2024'!K9 -> 37.71 | E9: ='Segments 2024'!J9-'Segments 2024'!I9 -> 43.25 | F9: ='Segments 2024'!N9-'Segments 2024'!M9 -> 13.21 | G9: ='Segments 2024'!F9-'Segments 2024'!E9 -> 2.39 | H9: ='Segments 2024'!G9-'Segments 2024'!H9 -> -0.17 | I9: ='Segments 2024'!P9-'Segments 2024'!O9 -> 41.13
A10: First account opened to receive wages or government money | B10: Access | C10: ='Segments 2024'!D10 -> 43.49 | D10: ='Segments 2024'!L10-'Segments 2024'!K10 -> 28.27 | E10: ='Segments 2024'!J10-'Segments 2024'!I10 -> 27.29 | F10: ='Segments 2024'!N10-'Segments 2024'!M10 -> 12.6 | G10: ='Segments 2024'!F10-'Segments 2024'!E10 -> 2.91 | H10: ='Segments 2024'!G10-'Segments 2024'!H10 -> -8.24 | I10: ='Segments 2024'!P10-'Segments 2024'!O10 -> 34.34
A11: No account: family member already has one | B11: Access | C11: ='Segments 2024'!D11 -> 16.51 | D11: ='Segments 2024'!L11-'Segments 2024'!K11 -> -16.04 | E11: ='Segments 2024'!J11-'Segments 2024'!I11 -> -12.94 | F11: ='Segments 2024'!N11-'Segments 2024'!M11 -> -4.12 | G11: ='Segments 2024'!F11-'Segments 2024'!E11 -> -4.73 | H11: ='Segments 2024'!G11-'Segments 2024'!H11 -> 4.32 | I11: ='Segments 2024'!P11-'Segments 2024'!O11 -> -21.33
A12: Could use an account without help if opened | B12: Access | C12: ='Segments 2024'!D12 -> 21.13 | D12: ='Segments 2024'!L12-'Segments 2024'!K12 -> -26.73 | E12: ='Segments 2024'!J12-'Segments 2024'!I12 -> -36.71 | F12: ='Segments 2024'!N12-'Segments 2024'!M12 -> -2.09 | G12: ='Segments 2024'!F12-'Segments 2024'!E12 -> -2.05 | H12: ='Segments 2024'!G12-'Segments 2024'!H12 -> -12.52 | I12: ='Segments 2024'!P12-'Segments 2024'!O12 -> -20.07
A13: Made or received a digital payment | B13: Digital payments | C13: ='Segments 2024'!D13 -> 62.38 | D13: ='Segments 2024'!L13-'Segments 2024'!K13 -> 39.62 | E13: ='Segments 2024'!J13-'Segments 2024'!I13 -> 40.42 | F13: ='Segments 2024'!N13-'Segments 2024'!M13 -> 8.67 | G13: ='Segments 2024'!F13-'Segments 2024'!E13 -> 2 | H13: ='Segments 2024'!G13-'Segments 2024'!H13 -> 5.15 | I13: ='Segments 2024'!P13-'Segments 2024'!O13 -> 39.33
A14: Made a digital payment | B14: Digital payments | C14: ='Segments 2024'!D14 -> 56.47 | D14: ='Segments 2024'!L14-'Segments 2024'!K14 -> 42.21 | E14: ='Segments 2024'!J14-'Segments 2024'!I14 -> 44.89 | F14: ='Segments 2024'!N14-'Segments 2024'!M14 -> 7 | G14: ='Segments 2024'!F14-'Segments 2024'!E14 -> -0.12 | H14: ='Segments 2024'!G14-'Segments 2024'!H14 -> 8.2 | I14: ='Segments 2024'!P14-'Segments 2024'!O14 -> 39.31
A15: Received digital payments | B15: Digital payments | C15: ='Segments 2024'!D15 -> 48.05 | D15: ='Segments 2024'!L15-'Segments 2024'!K15 -> 34.83 | E15: ='Segments 2024'!J15-'Segments 2024'!I15 -> 34.63 | F15: ='Segments 2024'!N15-'Segments 2024'!M15 -> 10.19 | G15: ='Segments 2024'!F15-'Segments 2024'!E15 -> 3.6 | H15: ='Segments 2024'!G15-'Segments 2024'!H15 -> -1.15 | I15: ='Segments 2024'!P15-'Segments 2024'!O15 -> 38.54
A16: Used a card or mobile phone to make payments | B16: Digital payments | C16: ='Segments 2024'!D16 -> 60.68 | D16: ='Segments 2024'!L16-'Segments 2024'!K16 -> 40.98 | E16: ='Segments 2024'!J16-'Segments 2024'!I16 -> 48.33 | F16: ='Segments 2024'!N16-'Segments 2024'!M16 -> 10.92 | G16: ='Segments 2024'!F16-'Segments 2024'!E16 -> 0.49 | H16: ='Segments 2024'!G16-'Segments 2024'!H16 -> 7.69 | I16: ='Segments 2024'!P16-'Segments 2024'!O16 -> 39.89
... A55: Used apps or websites to earn money | B55: Connectivity | C55: ='Segments 2024'!D55 -> 11.76 | D55: ='Segments 2024'!L55-'Segments 2024'!K55 -> 8.93 | E55: ='Segments 2024'!J55-'Segments 2024'!I55 -> 9.9 | F55: ='Segments 2024'!N55-'Segments 2024'!M55 -> 8.85 | G55: ='Segments 2024'!F55-'Segments 2024'!E55 -> -0.9 | H55: ='Segments 2024'!G55-'Segments 2024'!H55 -> 7.15 | I55: ='Segments 2024'!P55-'Segments 2024'!O55 -> 4.97

Sheet National 2024
A1: Vietnam Findex 2024: national figures without a published segment breakdown
A2: Percentage of adults aged 15+. These are the indicators the World Bank published for 2024 at national level only.
A4: Indicator id | B4: Indicator | C4: Theme | D4: 2024 (%)
A5: fin11d | B5: No account: insufficient funds | C5: Access | D5: 7.72
A6: fin11a | B6: No account: institutions are too far away | C6: Access | D6: 4.62
A7: inactive.t.d | B7: Has an inactive account | C7: Access | D7: 2.06
A8: fin11b | B8: No account: services are too expensive | C8: Access | D8: 2.03
A9: fin11f | B9: No account: lack of trust in institutions | C9: Access | D9: 1.92
A10: fin11_1 | B10: Ever had an account but does not now | C10: Access | D10: 1.5
A11: fin11c | B11: No account: lack of documentation | C11: Access | D11: 1.19
A12: con21 | B12: Received a call or SMS asking for money in the past year | C12: Connectivity | D12: 8.26
A13: con23 | B13: Received unwanted offensive messages or images | C13: Connectivity | D13: 2.04
A14: fin22a.22a1.22g.d | B14: Borrowed from a formal institution or mobile money | C14: Credit | D14: 8.11
A15: fin22a | B15: Borrowed from a formal financial institution | C15: Credit | D15: 7.67
A16: fin10 | B16: Owns a credit card | C16: Credit | D16: 5.82
... A36: fin24aN | B36: Emergency funds not possible at all | C36: Resilience | D36: 1.74

Sheet Trends
A1: Vietnam Findex headline indicators, 2011 to 2024
A2: Percentage of adults aged 15+. Blank means the question was not asked in that wave. Change columns show percentage points.
A4: Indicator id | B4: Indicator | C4: 2011 | D4: 2014 | E4: 2017 | F4: 2022 | G4: 2024 | H4: Change 2017 to 2024 | I4: Change 2022 to 2024
A5: account.t.d | B5: Has an account (any) | C5: 21.37 | D5: 30.95 | E5: 30.8 | F5: 56.27 | G5: 70.55 | H5: =IF(OR(E5="",G5=""),"",G5-E5) -> 39.75 | I5: =IF(OR(F5="",G5=""),"",G5-F5) -> 14.28
A6: fiaccount.t.d | B6: Bank or similar institution account | C6: 21.37 | D6: 30.86 | E6: 30.02 | F6: 56.06 | G6: 69.85 | H6: =IF(OR(E6="",G6=""),"",G6-E6) -> 39.83 | I6: =IF(OR(F6="",G6=""),"",G6-F6) -> 13.79
A7: mobileaccount.t.d | B7: Mobile money account | D7: 0.5 | E7: 3.5 | F7: 16.47 | G7: 38.72 | H7: =IF(OR(E7="",G7=""),"",G7-E7) -> 35.22 | I7: =IF(OR(F7="",G7=""),"",G7-F7) -> 22.25
A8: fin2.t.d | B8: Owns a debit card | C8: 14.59 | D8: 26.51 | E8: 26.74 | F8: 48.87 | G8: 64.82 | H8: =IF(OR(E8="",G8=""),"",G8-E8) -> 38.08 | I8: =IF(OR(F8="",G8=""),"",G8-F8) -> 15.95
A9: fin10 | B9: Owns a credit card | C9: 1.24 | D9: 1.93 | E9: 4.12 | F9: 5.64 | G9: 5.82 | H9: =IF(OR(E9="",G9=""),"",G9-E9) -> 1.7 | I9: =IF(OR(F9="",G9=""),"",G9-F9) -> 0.18
A10: g20.any | B10: Made or received a digital payment | D10: 19.38 | E10: 22.74 | F10: 45.98 | G10: 62.38 | H10: =IF(OR(E10="",G10=""),"",G10-E10) -> 39.64 | I10: =IF(OR(F10="",G10=""),"",G10-F10) -> 16.4
A11: g20.made | B11: Made a digital payment | D11: 10.59 | E11: 16.1 | F11: 41.93 | G11: 56.47 | H11: =IF(OR(E11="",G11=""),"",G11-E11) -> 40.37 | I11: =IF(OR(F11="",G11=""),"",G11-F11) -> 14.54
A12: g20.received | B12: Received digital payments | D12: 15.67 | E12: 14.92 | F12: 30.82 | G12: 48.05 | H12: =IF(OR(E12="",G12=""),"",G12-E12) -> 33.13 | I12: =IF(OR(F12="",G12=""),"",G12-F12) -> 17.23
A13: merchant.pay | B13: Made a digital merchant payment | F13: 24.26 | G13: 51.13 | H13: =IF(OR(E13="",G13=""),"",G13-E13) | I13: =IF(OR(F13="",G13=""),"",G13-F13) -> 26.87
A14: fin25e2 | B14: Used mobile or card for an in-store purchase | F14: 21.17 | G14: 48.26 | H14: =IF(OR(E14="",G14=""),"",G14-E14) | I14: =IF(OR(F14="",G14=""),"",G14-F14) -> 27.09
A15: fin26a | B15: Used mobile or internet to pay bills | E15: 6.53 | F15: 25.02 | G15: 45.5 | H15: =IF(OR(E15="",G15=""),"",G15-E15) -> 38.97 | I15: =IF(OR(F15="",G15=""),"",G15-F15) -> 20.48
A16: fin31a.31b | B16: Utility payment using an account | D16: 0.63 | E16: 3.35 | F16: 15.51 | G16: 32.7 | H16: =IF(OR(E16="",G16=""),"",G16-E16) -> 29.35 | I16: =IF(OR(F16="",G16=""),"",G16-F16) -> 17.19
A17: fin31d | B17: Utility payment in cash only | D17: 85.69 | E17: 69.13 | F17: 39.07 | G17: 25.06 | H17: =IF(OR(E17="",G17=""),"",G17-E17) -> -44.07 | I17: =IF(OR(F17="",G17=""),"",G17-F17) -> -14.01
A18: fin32.acc | B18: Received wages into an account | D18: 7.76 | E18: 10.43 | F18: 23.77 | G18: 36.99 | H18: =IF(OR(E18="",G18=""),"",G18-E18) -> 26.56 | I18: =IF(OR(F18="",G18=""),"",G18-F18) -> 13.22
A19: fin34b | B19: Received wages through a mobile phone | D19: 0 | E19: 0.57 | F19: 4.71 | G19: 19.66 | H19: =IF(OR(E19="",G19=""),"",G19-E19) -> 19.09 | I19: =IF(OR(F19="",G19=""),"",G19-F19) -> 14.95
A20: save.any.t.d | B20: Saved any money | D20: 63.3 | E20: 57.4 | F20: 52.4 | G20: 68.57 | H20: =IF(OR(E20="",G20=""),"",G20-E20) -> 11.17 | I20: =IF(OR(F20="",G20=""),"",G20-F20) -> 16.17
A21: fin17a | B21: Saved at a bank or similar institution | C21: 7.74 | D21: 14.61 | E21: 14.48 | F21: 19.86 | G21: 43.09 | H21: =IF(OR(E21="",G21=""),"",G21-E21) -> 28.61 | I21: =IF(OR(F21="",G21=""),"",G21-F21) -> 23.23
A22: fin17b | B22: Saved using a mobile money account | F22: 4.6 | G22: 10.06 | H22: =IF(OR(E22="",G22=""),"",G22-E22) | I22: =IF(OR(F22="",G22=""),"",G22-F22) -> 5.46
A23: borrow.any.t.d | B23: Borrowed any money | D23: 47.45 | E23: 49.02 | F23: 27.54 | G23: 43.2 | H23: =IF(OR(E23="",G23=""),"",G23-E23) -> -5.82 | I23: =IF(OR(F23="",G23=""),"",G23-F23) -> 15.66
A24: fin22a | B24: Borrowed from a formal financial institution | D24: 19.5 | E24: 21.72 | F24: 10.02 | G24: 7.67 | H24: =IF(OR(E24="",G24=""),"",G24-E24) -> -14.05 | I24: =IF(OR(F24="",G24=""),"",G24-F24) -> -2.35
A25: fin22b | B25: Borrowed from family or friends | D25: 29.88 | E25: 29.54 | F25: 17.94 | G25: 33.59 | H25: =IF(OR(E25="",G25=""),"",G25-E25) -> 4.05 | I25: =IF(OR(F25="",G25=""),"",G25-F25) -> 15.65
A26: fin22e | B26: Borrowed to start or operate a business | D26: 7.12 | E26: 14.79 | G26: 5.68 | H26: =IF(OR(E26="",G26=""),"",G26-E26) -> -9.11 | I26: =IF(OR(F26="",G26=""),"",G26-F26)
A27: fin22d | B27: Borrowed for health or medical purposes | D27: 7.72 | E27: 9.07 | F27: 3.88 | G27: 4.41 | H27: =IF(OR(E27="",G27=""),"",G27-E27) -> -4.66 | I27: =IF(OR(F27="",G27=""),"",G27-F27) -> 0.53
A28: inactive.t.d | B28: Has an inactive account | D28: 4.75 | E28: 2.88 | F28: 4.32 | G28: 2.06 | H28: =IF(OR(E28="",G28=""),"",G28-E28) -> -0.82 | I28: =IF(OR(F28="",G28=""),"",G28-F28) -> -2.26
A29: fin42 | B29: Received payments for agricultural products | D29: 28.46 | E29: 24.22 | F29: 16.34 | G29: 23.75 | H29: =IF(OR(E29="",G29=""),"",G29-E29) -> -0.47 | I29: =IF(OR(F29="",G29=""),"",G29-F29) -> 7.41
A30: fin43c | B30: Agricultural payments in cash only | D30: 28 | E30: 22.87 | F30: 14.38 | G30: 17.48 | H30: =IF(OR(E30="",G30=""),"",G30-E30) -> -5.39 | I30: =IF(OR(F30="",G30=""),"",G30-F30) -> 3.1

Sheet Vietnam reference
A1: Vietnam macro, banking and market reference figures
A2: Compiled 20 September 2026. Every row names its period and source. Re-check each figure against the source before citing it in a submission.
A4: Category | B4: Indicator | C4: Value | D4: Period | E4: Source
A5: Macro | B5: GDP growth | C5: 8.18% | D5: H1 2026 | E5: National Statistics Office
A6: Macro | B6: GDP growth | C6: 8.39% | D6: Q2 2026 | E6: National Statistics Office
A7: Macro | B7: GDP growth | C7: 7.83% | D7: Q1 2026 | E7: National Statistics Office
A8: Macro | B8: GDP growth forecast | C8: 7.3% | D8: FY2026 | E8: Bloomberg survey, July 2026
A9: Macro | B9: GDP growth forecast | C9: 6.8% | D9: FY2026 | E9: World Bank, May 2026
A10: Macro | B10: GDP growth forecast | C10: 7.2% | D10: FY2026 | E10: AMRO
A11: Macro | B11: CPI inflation | C11: 4.69% y/y | D11: June 2026 | E11: National Statistics Office
A12: Macro | B12: CPI inflation, average | C12: 4.38% | D12: H1 2026 | E12: National Statistics Office
A13: Macro | B13: Core inflation | C13: 4.50% | D13: June 2026 | E13: National Statistics Office
A14: Macro | B14: Retail sales | C14: VND 3,889.5tn, +12.9% nominal, +7.3% real | D14: H1 2026 | E14: National Statistics Office
A15: Macro | B15: FDI registered | C15: USD 34.65bn, +61.0% | D15: H1 2026 | E15: National Statistics Office
... A143: Regulation | B143: Circular 14/2025 | C143: Basel III capital requirements | D143: Phasing in | E143: State Bank of Vietnam

Sheet Sources
A1: Where to get the rest of the data
A2: Checked in a browser on 20 September 2026. Notes record what was actually found, including where a site turned out to be thinner than expected.
A4: Source | B4: Covers | C4: Link | D4: Notes
A5: World Bank Microdata Library | B5: Findex respondent-level file | C5: microdata.worldbank.org/index.php/catalog/7998 | D5: Verified: 1,000 cases, 199 variables, reference VNM_2024_FINDEX_v02_M. Free after accepting terms, no registration
A6: World Bank Open Data API | B6: Findex aggregates | C6: api.worldbank.org/v2/sources/28/country/VNM/series/all/data?format=json | D6: Verified: the source of this workbook. No key needed
A7: National Statistics Office | B7: GDP, CPI, FDI, trade, provincial data, 2026 census | C7: nso.gov.vn | D7: English releases available. Provincial series break at 1 July 2025 because of the merger
A8: State Bank of Vietnam | B8: Payment statistics, credit data, circulars | C8: sbv.gov.vn | D8: Aggregate only. Good for payments and regulation
A9: Vietstock | B9: Listed company financials | C9: finance.vietstock.vn/TICKER/tai-chinh.htm | D9: Verified: swap the ticker to change company. History to 2011. Pre-computes NIM, cost of funds and yield on earning assets. Has a data export menu
A10: CafeF | B10: Listed company financials | C10: s.cafef.vn | D10: Alternative structure, useful as a cross-check against Vietstock
A11: VPBank investor relations | B11: VPB filings and investor decks | C11: vpbank.com.vn/en/quan-he-nha-dau-tu | D11: Verified: statements 2011 to 2026, VAS and IFRS, consolidated and separate, searchable PDFs. Quarterly Performance Packs carry segment detail
A12: DNSE investor relations | B12: DSE filings and market share | C12: ir.dnse.com.vn/en | D12: Verified: English site, Q2 2026 published, annual reports 2024 and 2025, earnings releases with market share
A13: Techcombank investor relations | B13: TCB investor presentation | C13: techcombank.com | D13: The most detailed investor deck in Vietnamese banking
A14: MB | B14: MBB filings | C14: mbbank.com.vn | D14: English investor pages were partly unavailable when checked. Use Vietstock and HOSE instead
A15: HOSE | B15: Listings, filings, brokerage share | C15: hsx.vn | D15: Quarterly brokerage market share tables
... A23: App Store scraping | B23: App reviews | C23: app-store-scraper | D23: Same approach for iOS
